Workbook

Sheet aprile
A1: ID | B1: ISIN | C1: Coupon | D1: Maturity | E1: 45762 | F1: 45763 | G1: 45764 | H1: 45765 | I1: 45766 | J1: 45767 | K1: 45768 | L1: 45769 | M1: 45770 | N1: 45771 | O1: 45772 | P1: 45773 | Q1: 45774 | R1: 45775 | S1: 45776 | T1: 45777 | U1: 45778 | V1: 45779 | W1: 45780 | X1: 45781 | Y1: 45782 | Z1: 45783 | AA1: 45784 | AB1: 45785 | AC1: 45786 | AD1: 45787 | AE1: 45788 | AF1: 45789 | AG1: 45790 | AH1: 45791 | AI1: 45792
A2: 1 | B2: IT0003256820 | C2: 2.875 | D2: 01/02/2033 | E2: =_xlfn.XLOOKUP(B2,'15a'!$A:$A,'15a'!$G:$G,"pipino il breve") -> 116.49 | F2: =_xlfn.XLOOKUP(B2,'16a'!$A:$A,'16a'!$G:$G,"pipino il breve") -> 116.73 | G2: =_xlfn.XLOOKUP(B2,'17a'!$A:$A,'17a'!$G:$G,"pipino il breve") -> 117.14 | L2: =_xlfn.XLOOKUP(B2,'22a'!$A:$A,'22a'!$G:$G,"pipino il breve") -> 117.32 | M2: =_xlfn.XLOOKUP(B2,'23a'!$A:$A,'23a'!$G:$G,"pipino il breve") -> 117.15 | N2: =_xlfn.XLOOKUP(B2,'24a'!$A:$A,'24a'!$G:$G,"pipino il breve") -> 117.85 | O2: 117.52 | R2: =_xlfn.XLOOKUP(B2,'28'!$A:$A,'28'!$G:$G,"pipino il breve") -> 117.4 | S2: =_xlfn.XLOOKUP(B2,'29'!$A:$A,'29'!$G:$G,"pipino il breve") -> 117.36 | T2: =_xlfn.XLOOKUP(B2,'30'!$A:$A,'30'!$G:$G,"pipino il breve") -> 117.71 | V2: =_xlfn.XLOOKUP(B2,'2'!$A:$A,'2'!$G:$G,"pipino il breve") -> 117.24 | Y2: =_xlfn.XLOOKUP(B2,'5'!$A:$A,'5'!$G:$G,"pipino il breve") -> 117.4 | Z2: =_xlfn.XLOOKUP(B2,'6'!$A:$A,'6'!$G:$G,"pipino il breve") -> 117.25 | AA2: =_xlfn.XLOOKUP(B2,'7'!$A:$A,'7'!$G:$G,"pipino il breve") -> 117.67 | AB2: =_xlfn.XLOOKUP(B2,'8'!$A:$A,'8'!$G:$G,"pipino il breve") -> 117.56 | AC2: =_xlfn.XLOOKUP(B2,'9'!$A:$A,'9'!$G:$G,"pipino il breve") -> 117.32 | AF2: =_xlfn.XLOOKUP(B2,'12'!$A:$A,'12'!$G:$G,"pipino il breve") -> 116.74 | AG2: =_xlfn.XLOOKUP(B2,'13'!$A:$A,'13'!$G:$G,"pipino il breve") -> 116.59 | AH2: =_xlfn.XLOOKUP(B2,'14'!$A:$A,'14'!$G:$G,"pipino il breve") -> 116.5 | AI2: =_xlfn.XLOOKUP(B2,'15'!$A:$A,'15'!$G:$G,"pipino il breve") -> 116.98
A3: 2 | B3: IT0005240830 | C3: 1.1 | D3: 01/06/2027 | E3: =_xlfn.XLOOKUP(B3,'15a'!$A:$A,'15a'!$G:$G,"pipino il breve") -> 100.38 | F3: =_xlfn.XLOOKUP(B3,'16a'!$A:$A,'16a'!$G:$G,"pipino il breve") -> 100.49 | G3: =_xlfn.XLOOKUP(B3,'17a'!$A:$A,'17a'!$G:$G,"pipino il breve") -> 100.59 | L3: =_xlfn.XLOOKUP(B3,'22a'!$A:$A,'22a'!$G:$G,"pipino il breve") -> 100.63 | M3: =_xlfn.XLOOKUP(B3,'23a'!$A:$A,'23a'!$G:$G,"pipino il breve") -> 100.54 | N3: =_xlfn.XLOOKUP(B3,'24a'!$A:$A,'24a'!$G:$G,"pipino il breve") -> 100.68 | O3: 100.58 | R3: =_xlfn.XLOOKUP(B3,'28'!$A:$A,'28'!$G:$G,"pipino il breve") -> 100.6 | S3: =_xlfn.XLOOKUP(B3,'29'!$A:$A,'29'!$G:$G,"pipino il breve") -> 100.57 | T3: =_xlfn.XLOOKUP(B3,'30'!$A:$A,'30'!$G:$G,"pipino il breve") -> 100.63 | V3: =_xlfn.XLOOKUP(B3,'2'!$A:$A,'2'!$G:$G,"pipino il breve") -> 100.54 | Y3: =_xlfn.XLOOKUP(B3,'5'!$A:$A,'5'!$G:$G,"pipino il breve") -> 100.54 | Z3: =_xlfn.XLOOKUP(B3,'6'!$A:$A,'6'!$G:$G,"pipino il breve") -> 100.52 | AA3: =_xlfn.XLOOKUP(B3,'7'!$A:$A,'7'!$G:$G,"pipino il breve") -> 100.67 | AB3: =_xlfn.XLOOKUP(B3,'8'!$A:$A,'8'!$G:$G,"pipino il breve") -> 100.56 | AC3: =_xlfn.XLOOKUP(B3,'9'!$A:$A,'9'!$G:$G,"pipino il breve") -> 100.5 | AF3: =_xlfn.XLOOKUP(B3,'12'!$A:$A,'12'!$G:$G,"pipino il breve") -> 100.29 | AG3: =_xlfn.XLOOKUP(B3,'13'!$A:$A,'13'!$G:$G,"pipino il breve") -> 100.2 | AH3: =_xlfn.XLOOKUP(B3,'14'!$A:$A,'14'!$G:$G,"pipino il breve") -> 100.28 | AI3: =_xlfn.XLOOKUP(B3,'15'!$A:$A,'15'!$G:$G,"pipino il breve") -> 100.37
A4: 3 | B4: IT0005323032 | C4: 1 | D4: 01/02/2028 | E4: =_xlfn.XLOOKUP(B4,'15a'!$A:$A,'15a'!$G:$G,"pipino il breve") -> 99.61 | F4: =_xlfn.XLOOKUP(B4,'16a'!$A:$A,'16a'!$G:$G,"pipino il breve") -> 99.65 | G4: =_xlfn.XLOOKUP(B4,'17a'!$A:$A,'17a'!$G:$G,"pipino il breve") -> 99.81 | L4: =_xlfn.XLOOKUP(B4,'22a'!$A:$A,'22a'!$G:$G,"pipino il breve") -> 99.88 | M4: =_xlfn.XLOOKUP(B4,'23a'!$A:$A,'23a'!$G:$G,"pipino il breve") -> 99.6 | N4: =_xlfn.XLOOKUP(B4,'24a'!$A:$A,'24a'!$G:$G,"pipino il breve") -> 100 | O4: 99.79 | R4: =_xlfn.XLOOKUP(B4,'28'!$A:$A,'28'!$G:$G,"pipino il breve") -> 99.87 | S4: =_xlfn.XLOOKUP(B4,'29'!$A:$A,'29'!$G:$G,"pipino il breve") -> 99.85 | T4: =_xlfn.XLOOKUP(B4,'30'!$A:$A,'30'!$G:$G,"pipino il breve") -> 99.93 | V4: =_xlfn.XLOOKUP(B4,'2'!$A:$A,'2'!$G:$G,"pipino il breve") -> 99.9 | Y4: =_xlfn.XLOOKUP(B4,'5'!$A:$A,'5'!$G:$G,"pipino il breve") -> 99.82 | Z4: =_xlfn.XLOOKUP(B4,'6'!$A:$A,'6'!$G:$G,"pipino il breve") -> 99.81 | AA4: =_xlfn.XLOOKUP(B4,'7'!$A:$A,'7'!$G:$G,"pipino il breve") -> 99.92 | AB4: =_xlfn.XLOOKUP(B4,'8'!$A:$A,'8'!$G:$G,"pipino il breve") -> 99.84 | AC4: =_xlfn.XLOOKUP(B4,'9'!$A:$A,'9'!$G:$G,"pipino il breve") -> 99.77 | AF4: =_xlfn.XLOOKUP(B4,'12'!$A:$A,'12'!$G:$G,"pipino il breve") -> 99.47 | AG4: =_xlfn.XLOOKUP(B4,'13'!$A:$A,'13'!$G:$G,"pipino il breve") -> 99.41 | AH4: =_xlfn.XLOOKUP(B4,'14'!$A:$A,'14'!$G:$G,"pipino il breve") -> 99.45 | AI4: =_xlfn.XLOOKUP(B4,'15'!$A:$A,'15'!$G:$G,"pipino il breve") -> 99.5
A5: 4 | B5: IT0005365165 | C5: 1.5 | D5: 01/08/2029 | E5: =_xlfn.XLOOKUP(B5,'15a'!$A:$A,'15a'!$G:$G,"pipino il breve") -> 101.8 | F5: =_xlfn.XLOOKUP(B5,'16a'!$A:$A,'16a'!$G:$G,"pipino il breve") -> 102 | G5: =_xlfn.XLOOKUP(B5,'17a'!$A:$A,'17a'!$G:$G,"pipino il breve") -> 102.23 | L5: =_xlfn.XLOOKUP(B5,'22a'!$A:$A,'22a'!$G:$G,"pipino il breve") -> 102.28 | M5: =_xlfn.XLOOKUP(B5,'23a'!$A:$A,'23a'!$G:$G,"pipino il breve") -> 102.16 | N5: =_xlfn.XLOOKUP(B5,'24a'!$A:$A,'24a'!$G:$G,"pipino il breve") -> 102.58 | O5: 102.36 | R5: =_xlfn.XLOOKUP(B5,'28'!$A:$A,'28'!$G:$G,"pipino il breve") -> 102.35 | S5: =_xlfn.XLOOKUP(B5,'29'!$A:$A,'29'!$G:$G,"pipino il breve") -> 102.28 | T5: =_xlfn.XLOOKUP(B5,'30'!$A:$A,'30'!$G:$G,"pipino il breve") -> 102.48 | V5: =_xlfn.XLOOKUP(B5,'2'!$A:$A,'2'!$G:$G,"pipino il breve") -> 102.31 | Y5: =_xlfn.XLOOKUP(B5,'5'!$A:$A,'5'!$G:$G,"pipino il breve") -> 102.3 | Z5: =_xlfn.XLOOKUP(B5,'6'!$A:$A,'6'!$G:$G,"pipino il breve") -> 102.29 | AA5: =_xlfn.XLOOKUP(B5,'7'!$A:$A,'7'!$G:$G,"pipino il breve") -> 102.52 | AB5: =_xlfn.XLOOKUP(B5,'8'!$A:$A,'8'!$G:$G,"pipino il breve") -> 102.23 | AC5: =_xlfn.XLOOKUP(B5,'9'!$A:$A,'9'!$G:$G,"pipino il breve") -> 102.25 | AF5: =_xlfn.XLOOKUP(B5,'12'!$A:$A,'12'!$G:$G,"pipino il breve") -> 101.84 | AG5: =_xlfn.XLOOKUP(B5,'13'!$A:$A,'13'!$G:$G,"pipino il breve") -> 101.79 | AH5: =_xlfn.XLOOKUP(B5,'14'!$A:$A,'14'!$G:$G,"pipino il breve") -> 101.77 | AI5: =_xlfn.XLOOKUP(B5,'15'!$A:$A,'15'!$G:$G,"pipino il breve") -> 102.29
A6: 5 | B6: IT0005582421 | C6: 2.075 | D6: 01/10/2039 | E6: =_xlfn.XLOOKUP(B6,'15a'!$A:$A,'15a'!$G:$G,"pipino il breve") -> 101.3 | F6: =_xlfn.XLOOKUP(B6,'16a'!$A:$A,'16a'!$G:$G,"pipino il breve") -> 101.56 | G6: =_xlfn.XLOOKUP(B6,'17a'!$A:$A,'17a'!$G:$G,"pipino il breve") -> 101.94 | L6: =_xlfn.XLOOKUP(B6,'22a'!$A:$A,'22a'!$G:$G,"pipino il breve") -> 102.22 | M6: =_xlfn.XLOOKUP(B6,'23a'!$A:$A,'23a'!$G:$G,"pipino il breve") -> 102.05 | N6: =_xlfn.XLOOKUP(B6,'24a'!$A:$A,'24a'!$G:$G,"pipino il breve") -> 102.92 | O6: 102.48 | R6: =_xlfn.XLOOKUP(B6,'28'!$A:$A,'28'!$G:$G,"pipino il breve") -> 102.27 | S6: =_xlfn.XLOOKUP(B6,'29'!$A:$A,'29'!$G:$G,"pipino il breve") -> 102.21 | T6: =_xlfn.XLOOKUP(B6,'30'!$A:$A,'30'!$G:$G,"pipino il breve") -> 102.58 | V6: =_xlfn.XLOOKUP(B6,'2'!$A:$A,'2'!$G:$G,"pipino il breve") -> 102.18 | Y6: =_xlfn.XLOOKUP(B6,'5'!$A:$A,'5'!$G:$G,"pipino il breve") -> 102.15 | Z6: =_xlfn.XLOOKUP(B6,'6'!$A:$A,'6'!$G:$G,"pipino il breve") -> 101.96 | AA6: =_xlfn.XLOOKUP(B6,'7'!$A:$A,'7'!$G:$G,"pipino il breve") -> 102.73 | AB6: =_xlfn.XLOOKUP(B6,'8'!$A:$A,'8'!$G:$G,"pipino il breve") -> 102.5 | AC6: =_xlfn.XLOOKUP(B6,'9'!$A:$A,'9'!$G:$G,"pipino il breve") -> 102.1 | AF6: =_xlfn.XLOOKUP(B6,'12'!$A:$A,'12'!$G:$G,"pipino il breve") -> 101.61 | AG6: =_xlfn.XLOOKUP(B6,'13'!$A:$A,'13'!$G:$G,"pipino il breve") -> 101.22 | AH6: =_xlfn.XLOOKUP(B6,'14'!$A:$A,'14'!$G:$G,"pipino il breve") -> 101.24 | AI6: =_xlfn.XLOOKUP(B6,'15'!$A:$A,'15'!$G:$G,"pipino il breve") -> 101.99
A7: 6 | B7: IT0005436693 | C7: 0.3 | D7: 01/08/2031 | E7: =_xlfn.XLOOKUP(B7,'15a'!$A:$A,'15a'!$G:$G,"pipino il breve") -> 86.06 | F7: =_xlfn.XLOOKUP(B7,'16a'!$A:$A,'16a'!$G:$G,"pipino il breve") -> 86.25 | G7: =_xlfn.XLOOKUP(B7,'17a'!$A:$A,'17a'!$G:$G,"pipino il breve") -> 86.6 | L7: =_xlfn.XLOOKUP(B7,'22a'!$A:$A,'22a'!$G:$G,"pipino il breve") -> 86.71 | M7: =_xlfn.XLOOKUP(B7,'23a'!$A:$A,'23a'!$G:$G,"pipino il breve") -> 86.63 | N7: =_xlfn.XLOOKUP(B7,'24a'!$A:$A,'24a'!$G:$G,"pipino il breve") -> 87.23 | O7: 86.93 | R7: =_xlfn.XLOOKUP(B7,'28'!$A:$A,'28'!$G:$G,"pipino il breve") -> 86.88 | S7: =_xlfn.XLOOKUP(B7,'29'!$A:$A,'29'!$G:$G,"pipino il breve") -> 86.91 | T7: =_xlfn.XLOOKUP(B7,'30'!$A:$A,'30'!$G:$G,"pipino il breve") -> 87.13 | V7: =_xlfn.XLOOKUP(B7,'2'!$A:$A,'2'!$G:$G,"pipino il breve") -> 86.86 | Y7: =_xlfn.XLOOKUP(B7,'5'!$A:$A,'5'!$G:$G,"pipino il breve") -> 86.92 | Z7: =_xlfn.XLOOKUP(B7,'6'!$A:$A,'6'!$G:$G,"pipino il breve") -> 86.92 | AA7: =_xlfn.XLOOKUP(B7,'7'!$A:$A,'7'!$G:$G,"pipino il breve") -> 87.2 | AB7: =_xlfn.XLOOKUP(B7,'8'!$A:$A,'8'!$G:$G,"pipino il breve") -> 87.1 | AC7: =_xlfn.XLOOKUP(B7,'9'!$A:$A,'9'!$G:$G,"pipino il breve") -> 86.94 | AF7: =_xlfn.XLOOKUP(B7,'12'!$A:$A,'12'!$G:$G,"pipino il breve") -> 86.51 | AG7: =_xlfn.XLOOKUP(B7,'13'!$A:$A,'13'!$G:$G,"pipino il breve") -> 86.4 | AH7: =_xlfn.XLOOKUP(B7,'14'!$A:$A,'14'!$G:$G,"pipino il breve") -> 86.36 | AI7: =_xlfn.XLOOKUP(B7,'15'!$A:$A,'15'!$G:$G,"pipino il breve") -> 86.7
A8: 7 | B8: IT0004923998 | C8: 2.375 | D8: 01/09/2044 | E8: =_xlfn.XLOOKUP(B8,'15a'!$A:$A,'15a'!$G:$G,"pipino il breve") -> 107.55 | F8: =_xlfn.XLOOKUP(B8,'16a'!$A:$A,'16a'!$G:$G,"pipino il breve") -> 107.67 | G8: =_xlfn.XLOOKUP(B8,'17a'!$A:$A,'17a'!$G:$G,"pipino il breve") -> 108.13 | L8: =_xlfn.XLOOKUP(B8,'22a'!$A:$A,'22a'!$G:$G,"pipino il breve") -> 108.37 | M8: =_xlfn.XLOOKUP(B8,'23a'!$A:$A,'23a'!$G:$G,"pipino il breve") -> 108.25 | N8: =_xlfn.XLOOKUP(B8,'24a'!$A:$A,'24a'!$G:$G,"pipino il breve") -> 109.32 | O8: 108.74 | R8: =_xlfn.XLOOKUP(B8,'28'!$A:$A,'28'!$G:$G,"pipino il breve") -> 108.57 | S8: =_xlfn.XLOOKUP(B8,'29'!$A:$A,'29'!$G:$G,"pipino il breve") -> 108.41 | T8: =_xlfn.XLOOKUP(B8,'30'!$A:$A,'30'!$G:$G,"pipino il breve") -> 108.82 | V8: =_xlfn.XLOOKUP(B8,'2'!$A:$A,'2'!$G:$G,"pipino il breve") -> 108.14 | Y8: =_xlfn.XLOOKUP(B8,'5'!$A:$A,'5'!$G:$G,"pipino il breve") -> 108.34 | Z8: =_xlfn.XLOOKUP(B8,'6'!$A:$A,'6'!$G:$G,"pipino il breve") -> 108.05 | AA8: =_xlfn.XLOOKUP(B8,'7'!$A:$A,'7'!$G:$G,"pipino il breve") -> 108.96 | AB8: =_xlfn.XLOOKUP(B8,'8'!$A:$A,'8'!$G:$G,"pipino il breve") -> 108.58 | AC8: =_xlfn.XLOOKUP(B8,'9'!$A:$A,'9'!$G:$G,"pipino il breve") -> 108.15 | AF8: =_xlfn.XLOOKUP(B8,'12'!$A:$A,'12'!$G:$G,"pipino il breve") -> 107.6 | AG8: =_xlfn.XLOOKUP(B8,'13'!$A:$A,'13'!$G:$G,"pipino il breve") -> 107.16 | AH8: =_xlfn.XLOOKUP(B8,'14'!$A:$A,'14'!$G:$G,"pipino il breve") -> 107.17 | AI8: =_xlfn.XLOOKUP(B8,'15'!$A:$A,'15'!$G:$G,"pipino il breve") -> 108.08
A9: 8 | B9: IT0005024234 | C9: 1.75 | D9: 01/03/2030 | E9: =_xlfn.XLOOKUP(B9,'15a'!$A:$A,'15a'!$G:$G,"pipino il breve") -> 103.77 | F9: =_xlfn.XLOOKUP(B9,'16a'!$A:$A,'16a'!$G:$G,"pipino il breve") -> 103.97 | G9: =_xlfn.XLOOKUP(B9,'17a'!$A:$A,'17a'!$G:$G,"pipino il breve") -> 104.25 | L9: =_xlfn.XLOOKUP(B9,'22a'!$A:$A,'22a'!$G:$G,"pipino il breve") -> 104.33 | M9: =_xlfn.XLOOKUP(B9,'23a'!$A:$A,'23a'!$G:$G,"pipino il breve") -> 104.24 | N9: =_xlfn.XLOOKUP(B9,'24a'!$A:$A,'24a'!$G:$G,"pipino il breve") -> 104.66 | O9: 104.38 | R9: =_xlfn.XLOOKUP(B9,'28'!$A:$A,'28'!$G:$G,"pipino il breve") -> 104.46 | S9: =_xlfn.XLOOKUP(B9,'29'!$A:$A,'29'!$G:$G,"pipino il breve") -> 104.4 | T9: =_xlfn.XLOOKUP(B9,'30'!$A:$A,'30'!$G:$G,"pipino il breve") -> 104.51 | V9: =_xlfn.XLOOKUP(B9,'2'!$A:$A,'2'!$G:$G,"pipino il breve") -> 104.37 | Y9: =_xlfn.XLOOKUP(B9,'5'!$A:$A,'5'!$G:$G,"pipino il breve") -> 104.36 | Z9: =_xlfn.XLOOKUP(B9,'6'!$A:$A,'6'!$G:$G,"pipino il breve") -> 104.4 | AA9: =_xlfn.XLOOKUP(B9,'7'!$A:$A,'7'!$G:$G,"pipino il breve") -> 104.6 | AB9: =_xlfn.XLOOKUP(B9,'8'!$A:$A,'8'!$G:$G,"pipino il breve") -> 104.45 | AC9: =_xlfn.XLOOKUP(B9,'9'!$A:$A,'9'!$G:$G,"pipino il breve") -> 104.28 | AF9: =_xlfn.XLOOKUP(B9,'12'!$A:$A,'12'!$G:$G,"pipino il breve") -> 103.84 | AG9: =_xlfn.XLOOKUP(B9,'13'!$A:$A,'13'!$G:$G,"pipino il breve") -> 103.78 | AH9: =_xlfn.XLOOKUP(B9,'14'!$A:$A,'14'!$G:$G,"pipino il breve") -> 103.75 | AI9: =_xlfn.XLOOKUP(B9,'15'!$A:$A,'15'!$G:$G,"pipino il breve") -> 103.99
A10: 9 | B10: IT0005094088 | C10: 0.825 | D10: 01/03/2032 | E10: =_xlfn.XLOOKUP(B10,'15a'!$A:$A,'15a'!$G:$G,"pipino il breve") -> 90.75 | F10: =_xlfn.XLOOKUP(B10,'16a'!$A:$A,'16a'!$G:$G,"pipino il breve") -> 91 | G10: =_xlfn.XLOOKUP(B10,'17a'!$A:$A,'17a'!$G:$G,"pipino il breve") -> 91.34 | L10: =_xlfn.XLOOKUP(B10,'22a'!$A:$A,'22a'!$G:$G,"pipino il breve") -> 91.5 | M10: =_xlfn.XLOOKUP(B10,'23a'!$A:$A,'23a'!$G:$G,"pipino il breve") -> 91.41 | N10: =_xlfn.XLOOKUP(B10,'24a'!$A:$A,'24a'!$G:$G,"pipino il breve") -> 91.97 | O10: 91.72 | R10: =_xlfn.XLOOKUP(B10,'28'!$A:$A,'28'!$G:$G,"pipino il breve") -> 91.68 | S10: =_xlfn.XLOOKUP(B10,'29'!$A:$A,'29'!$G:$G,"pipino il breve") -> 91.64 | T10: =_xlfn.XLOOKUP(B10,'30'!$A:$A,'30'!$G:$G,"pipino il breve") -> 91.9 | V10: =_xlfn.XLOOKUP(B10,'2'!$A:$A,'2'!$G:$G,"pipino il breve") -> 91.64 | Y10: =_xlfn.XLOOKUP(B10,'5'!$A:$A,'5'!$G:$G,"pipino il breve") -> 91.67 | Z10: =_xlfn.XLOOKUP(B10,'6'!$A:$A,'6'!$G:$G,"pipino il breve") -> 91.62 | AA10: =_xlfn.XLOOKUP(B10,'7'!$A:$A,'7'!$G:$G,"pipino il breve") -> 92 | AB10: =_xlfn.XLOOKUP(B10,'8'!$A:$A,'8'!$G:$G,"pipino il breve") -> 91.91 | AC10: =_xlfn.XLOOKUP(B10,'9'!$A:$A,'9'!$G:$G,"pipino il breve") -> 91.66 | AF10: =_xlfn.XLOOKUP(B10,'12'!$A:$A,'12'!$G:$G,"pipino il breve") -> 91.23 | AG10: =_xlfn.XLOOKUP(B10,'13'!$A:$A,'13'!$G:$G,"pipino il breve") -> 91.1 | AH10: =_xlfn.XLOOKUP(B10,'14'!$A:$A,'14'!$G:$G,"pipino il breve") -> 91.08 | AI10: =_xlfn.XLOOKUP(B10,'15'!$A:$A,'15'!$G:$G,"pipino il breve") -> 91.43
A11: 10 | B11: IT0005170839 | C11: 0.8 | D11: 01/06/2026 | E11: =_xlfn.XLOOKUP(B11,'15a'!$A:$A,'15a'!$G:$G,"pipino il breve") -> 99.55 | F11: =_xlfn.XLOOKUP(B11,'16a'!$A:$A,'16a'!$G:$G,"pipino il breve") -> 99.62 | G11: =_xlfn.XLOOKUP(B11,'17a'!$A:$A,'17a'!$G:$G,"pipino il breve") -> 99.7 | L11: =_xlfn.XLOOKUP(B11,'22a'!$A:$A,'22a'!$G:$G,"pipino il breve") -> 99.75 | M11: =_xlfn.XLOOKUP(B11,'23a'!$A:$A,'23a'!$G:$G,"pipino il breve") -> 99.65 | N11: =_xlfn.XLOOKUP(B11,'24a'!$A:$A,'24a'!$G:$G,"pipino il breve") -> 99.77 | O11: 99.72 | R11: =_xlfn.XLOOKUP(B11,'28'!$A:$A,'28'!$G:$G,"pipino il breve") -> 99.75 | S11: =_xlfn.XLOOKUP(B11,'29'!$A:$A,'29'!$G:$G,"pipino il breve") -> 99.72 | T11: =_xlfn.XLOOKUP(B11,'30'!$A:$A,'30'!$G:$G,"pipino il breve") -> 99.76 | V11: =_xlfn.XLOOKUP(B11,'2'!$A:$A,'2'!$G:$G,"pipino il breve") -> 99.68 | Y11: =_xlfn.XLOOKUP(B11,'5'!$A:$A,'5'!$G:$G,"pipino il breve") -> 99.7 | Z11: =_xlfn.XLOOKUP(B11,'6'!$A:$A,'6'!$G:$G,"pipino il breve") -> 99.71 | AA11: =_xlfn.XLOOKUP(B11,'7'!$A:$A,'7'!$G:$G,"pipino il breve") -> 99.75 | AB11: =_xlfn.XLOOKUP(B11,'8'!$A:$A,'8'!$G:$G,"pipino il breve") -> 99.73 | AC11: =_xlfn.XLOOKUP(B11,'9'!$A:$A,'9'!$G:$G,"pipino il breve") -> 99.75 | AF11: =_xlfn.XLOOKUP(B11,'12'!$A:$A,'12'!$G:$G,"pipino il breve") -> 99.62 | AG11: =_xlfn.XLOOKUP(B11,'13'!$A:$A,'13'!$G:$G,"pipino il breve") -> 99.9 | AH11: =_xlfn.XLOOKUP(B11,'14'!$A:$A,'14'!$G:$G,"pipino il breve") -> 99.63 | AI11: =_xlfn.XLOOKUP(B11,'15'!$A:$A,'15'!$G:$G,"pipino il breve") -> 99.64
A12: 11 | B12: IT0005177909 | C12: 1.125 | D12: 01/09/2036 | E12: =_xlfn.XLOOKUP(B12,'15a'!$A:$A,'15a'!$G:$G,"pipino il breve") -> 86.27 | F12: =_xlfn.XLOOKUP(B12,'16a'!$A:$A,'16a'!$G:$G,"pipino il breve") -> 86.55 | G12: =_xlfn.XLOOKUP(B12,'17a'!$A:$A,'17a'!$G:$G,"pipino il breve") -> 86.94 | L12: =_xlfn.XLOOKUP(B12,'22a'!$A:$A,'22a'!$G:$G,"pipino il breve") -> 87.18 | M12: =_xlfn.XLOOKUP(B12,'23a'!$A:$A,'23a'!$G:$G,"pipino il breve") -> 87.03 | N12: =_xlfn.XLOOKUP(B12,'24a'!$A:$A,'24a'!$G:$G,"pipino il breve") -> 87.71 | O12: 87.26 | R12: =_xlfn.XLOOKUP(B12,'28'!$A:$A,'28'!$G:$G,"pipino il breve") -> 87.17 | S12: =_xlfn.XLOOKUP(B12,'29'!$A:$A,'29'!$G:$G,"pipino il breve") -> 87.16 | T12: =_xlfn.XLOOKUP(B12,'30'!$A:$A,'30'!$G:$G,"pipino il breve") -> 87.48 | V12: =_xlfn.XLOOKUP(B12,'2'!$A:$A,'2'!$G:$G,"pipino il breve") -> 87.14 | Y12: =_xlfn.XLOOKUP(B12,'5'!$A:$A,'5'!$G:$G,"pipino il breve") -> 87.23 | Z12: =_xlfn.XLOOKUP(B12,'6'!$A:$A,'6'!$G:$G,"pipino il breve") -> 87.12 | AA12: =_xlfn.XLOOKUP(B12,'7'!$A:$A,'7'!$G:$G,"pipino il breve") -> 87.58 | AB12: =_xlfn.XLOOKUP(B12,'8'!$A:$A,'8'!$G:$G,"pipino il breve") -> 87.54 | AC12: =_xlfn.XLOOKUP(B12,'9'!$A:$A,'9'!$G:$G,"pipino il breve") -> 87.34 | AF12: =_xlfn.XLOOKUP(B12,'12'!$A:$A,'12'!$G:$G,"pipino il breve") -> 86.82 | AG12: =_xlfn.XLOOKUP(B12,'13'!$A:$A,'13'!$G:$G,"pipino il breve") -> 86.62 | AH12: =_xlfn.XLOOKUP(B12,'14'!$A:$A,'14'!$G:$G,"pipino il breve") -> 86.51 | AI12: =_xlfn.XLOOKUP(B12,'15'!$A:$A,'15'!$G:$G,"pipino il breve") -> 87.11
A13: 12 | B13: IT0005273013 | C13: 1.725 | D13: 01/03/2048 | E13: =_xlfn.XLOOKUP(B13,'15a'!$A:$A,'15a'!$G:$G,"pipino il breve") -> 88.47 | F13: =_xlfn.XLOOKUP(B13,'16a'!$A:$A,'16a'!$G:$G,"pipino il breve") -> 88.72 | G13: =_xlfn.XLOOKUP(B13,'17a'!$A:$A,'17a'!$G:$G,"pipino il breve") -> 88.64 | L13: =_xlfn.XLOOKUP(B13,'22a'!$A:$A,'22a'!$G:$G,"pipino il breve") -> 89.2 | M13: =_xlfn.XLOOKUP(B13,'23a'!$A:$A,'23a'!$G:$G,"pipino il breve") -> 89 | N13: =_xlfn.XLOOKUP(B13,'24a'!$A:$A,'24a'!$G:$G,"pipino il breve") -> 90.05 | O13: 89.66 | R13: =_xlfn.XLOOKUP(B13,'28'!$A:$A,'28'!$G:$G,"pipino il breve") -> 89.28 | S13: =_xlfn.XLOOKUP(B13,'29'!$A:$A,'29'!$G:$G,"pipino il breve") -> 89.16 | T13: =_xlfn.XLOOKUP(B13,'30'!$A:$A,'30'!$G:$G,"pipino il breve") -> 89.6 | V13: =_xlfn.XLOOKUP(B13,'2'!$A:$A,'2'!$G:$G,"pipino il breve") -> 88.93 | Y13: =_xlfn.XLOOKUP(B13,'5'!$A:$A,'5'!$G:$G,"pipino il breve") -> 89 | Z13: =_xlfn.XLOOKUP(B13,'6'!$A:$A,'6'!$G:$G,"pipino il breve") -> 88.78 | AA13: =_xlfn.XLOOKUP(B13,'7'!$A:$A,'7'!$G:$G,"pipino il breve") -> 89.65 | AB13: =_xlfn.XLOOKUP(B13,'8'!$A:$A,'8'!$G:$G,"pipino il breve") -> 89.16 | AC13: =_xlfn.XLOOKUP(B13,'9'!$A:$A,'9'!$G:$G,"pipino il breve") -> 88.85 | AF13: =_xlfn.XLOOKUP(B13,'12'!$A:$A,'12'!$G:$G,"pipino il breve") -> 88.36 | AG13: =_xlfn.XLOOKUP(B13,'13'!$A:$A,'13'!$G:$G,"pipino il breve") -> 87.93 | AH13: =_xlfn.XLOOKUP(B13,'14'!$A:$A,'14'!$G:$G,"pipino il breve") -> 87.9 | AI13: =_xlfn.XLOOKUP(B13,'15'!$A:$A,'15'!$G:$G,"pipino il breve") -> 88.83
... A52: 51 | B52: IT0001444378 | C52: 3 | D52: 01/05/2031 | E52: =_xlfn.XLOOKUP(B52,'15a'!$A:$A,'15a'!$G:$G,"pipino il breve") -> 116.79 | F52: =_xlfn.XLOOKUP(B52,'16a'!$A:$A,'16a'!$G:$G,"pipino il breve") -> 116.94 | G52: =_xlfn.XLOOKUP(B52,'17a'!$A:$A,'17a'!$G:$G,"pipino il breve") -> 117.23 | L52: =_xlfn.XLOOKUP(B52,'22a'!$A:$A,'22a'!$G:$G,"pipino il breve") -> 117.43 | M52: =_xlfn.XLOOKUP(B52,'23a'!$A:$A,'23a'!$G:$G,"pipino il breve") -> 117.28 | N52: =_xlfn.XLOOKUP(B52,'24a'!$A:$A,'24a'!$G:$G,"pipino il breve") -> 117.93 | O52: 117.52 | R52: =_xlfn.XLOOKUP(B52,'28'!$A:$A,'28'!$G:$G,"pipino il breve") -> 117.51 | S52: =_xlfn.XLOOKUP(B52,'29'!$A:$A,'29'!$G:$G,"pipino il breve") -> 117.53 | T52: =_xlfn.XLOOKUP(B52,'30'!$A:$A,'30'!$G:$G,"pipino il breve") -> 117.65 | V52: =_xlfn.XLOOKUP(B52,'2'!$A:$A,'2'!$G:$G,"pipino il breve") -> 117.37 | Y52: =_xlfn.XLOOKUP(B52,'5'!$A:$A,'5'!$G:$G,"pipino il breve") -> 117.38 | Z52: =_xlfn.XLOOKUP(B52,'6'!$A:$A,'6'!$G:$G,"pipino il breve") -> 117.38 | AA52: =_xlfn.XLOOKUP(B52,'7'!$A:$A,'7'!$G:$G,"pipino il breve") -> 117.68 | AB52: =_xlfn.XLOOKUP(B52,'8'!$A:$A,'8'!$G:$G,"pipino il breve") -> 117.55 | AC52: =_xlfn.XLOOKUP(B52,'9'!$A:$A,'9'!$G:$G,"pipino il breve") -> 117.38 | AF52: =_xlfn.XLOOKUP(B52,'12'!$A:$A,'12'!$G:$G,"pipino il breve") -> 116.86 | AG52: =_xlfn.XLOOKUP(B52,'13'!$A:$A,'13'!$G:$G,"pipino il breve") -> 116.72 | AH52: =_xlfn.XLOOKUP(B52,'14'!$A:$A,'14'!$G:$G,"pipino il breve") -> 116.68 | AI52: =_xlfn.XLOOKUP(B52,'15'!$A:$A,'15'!$G:$G,"pipino il breve") -> 117
A53: 52 | B53: IT0005090318 | C53: 0.75 | D53: 01/06/2025 | E53: 99.9 | F53: 99.91 | G53: 99.93 | L53: 99.92 | M53: 99.93 | N53: 99.93 | O53: 99.934 | R53: =_xlfn.XLOOKUP(B53,'28'!$A:$A,'28'!$G:$G,"pipino il breve") -> 99.939 | S53: =_xlfn.XLOOKUP(B53,'29'!$A:$A,'29'!$G:$G,"pipino il breve") -> 99.936 | T53: =_xlfn.XLOOKUP(B53,'30'!$A:$A,'30'!$G:$G,"pipino il breve") -> 99.931 | V53: =_xlfn.XLOOKUP(B53,'2'!$A:$A,'2'!$G:$G,"pipino il breve") -> 99.941 | Y53: =_xlfn.XLOOKUP(B53,'5'!$A:$A,'5'!$G:$G,"pipino il breve") -> 99.941 | Z53: =_xlfn.XLOOKUP(B53,'6'!$A:$A,'6'!$G:$G,"pipino il breve") -> 99.952 | AA53: =_xlfn.XLOOKUP(B53,'7'!$A:$A,'7'!$G:$G,"pipino il breve") -> 99.959 | AB53: =_xlfn.XLOOKUP(B53,'8'!$A:$A,'8'!$G:$G,"pipino il breve") -> 99.958 | AC53: =_xlfn.XLOOKUP(B53,'9'!$A:$A,'9'!$G:$G,"pipino il breve") -> 99.959 | AF53: =_xlfn.XLOOKUP(B53,'12'!$A:$A,'12'!$G:$G,"pipino il breve") -> 99.969 | AG53: =_xlfn.XLOOKUP(B53,'13'!$A:$A,'13'!$G:$G,"pipino il breve") -> 99.971 | AH53: =_xlfn.XLOOKUP(B53,'14'!$A:$A,'14'!$G:$G,"pipino il breve") -> 99.965 | AI53: =_xlfn.XLOOKUP(B53,'15'!$A:$A,'15'!$G:$G,"pipino il breve") -> 99.97
A54: 53 | B54: IT0005403396 | C54: 0.475 | D54: 01/08/2030 | E54: =_xlfn.XLOOKUP(B54,'15a'!$A:$A,'15a'!$G:$G,"pipino il breve") -> 90.81 | F54: =_xlfn.XLOOKUP(B54,'16a'!$A:$A,'16a'!$G:$G,"pipino il breve") -> 91.02 | G54: =_xlfn.XLOOKUP(B54,'17a'!$A:$A,'17a'!$G:$G,"pipino il breve") -> 91.3 | L54: =_xlfn.XLOOKUP(B54,'22a'!$A:$A,'22a'!$G:$G,"pipino il breve") -> 91.45 | M54: =_xlfn.XLOOKUP(B54,'23a'!$A:$A,'23a'!$G:$G,"pipino il breve") -> 91.31 | N54: =_xlfn.XLOOKUP(B54,'24a'!$A:$A,'24a'!$G:$G,"pipino il breve") -> 91.8 | O54: 91.55 | R54: =_xlfn.XLOOKUP(B54,'28'!$A:$A,'28'!$G:$G,"pipino il breve") -> 91.54 | S54: =_xlfn.XLOOKUP(B54,'29'!$A:$A,'29'!$G:$G,"pipino il breve") -> 91.57 | T54: =_xlfn.XLOOKUP(B54,'30'!$A:$A,'30'!$G:$G,"pipino il breve") -> 91.71 | V54: =_xlfn.XLOOKUP(B54,'2'!$A:$A,'2'!$G:$G,"pipino il breve") -> 91.48 | Y54: =_xlfn.XLOOKUP(B54,'5'!$A:$A,'5'!$G:$G,"pipino il breve") -> 91.51 | Z54: =_xlfn.XLOOKUP(B54,'6'!$A:$A,'6'!$G:$G,"pipino il breve") -> 91.53 | AA54: =_xlfn.XLOOKUP(B54,'7'!$A:$A,'7'!$G:$G,"pipino il breve") -> 91.76 | AB54: =_xlfn.XLOOKUP(B54,'8'!$A:$A,'8'!$G:$G,"pipino il breve") -> 91.68 | AC54: =_xlfn.XLOOKUP(B54,'9'!$A:$A,'9'!$G:$G,"pipino il breve") -> 91.55 | AF54: =_xlfn.XLOOKUP(B54,'12'!$A:$A,'12'!$G:$G,"pipino il breve") -> 91.09 | AG54: =_xlfn.XLOOKUP(B54,'13'!$A:$A,'13'!$G:$G,"pipino il breve") -> 91.07 | AH54: =_xlfn.XLOOKUP(B54,'14'!$A:$A,'14'!$G:$G,"pipino il breve") -> 90.96 | AI54: =_xlfn.XLOOKUP(B54,'15'!$A:$A,'15'!$G:$G,"pipino il breve") -> 91.25
A55: 54 | B55: IT0005544082 | C55: 2.175 | D55: 01/11/2033 | E55: =_xlfn.XLOOKUP(B55,'15a'!$A:$A,'15a'!$G:$G,"pipino il breve") -> 106.63 | F55: =_xlfn.XLOOKUP(B55,'16a'!$A:$A,'16a'!$G:$G,"pipino il breve") -> 106.83 | G55: =_xlfn.XLOOKUP(B55,'17a'!$A:$A,'17a'!$G:$G,"pipino il breve") -> 107.33 | L55: =_xlfn.XLOOKUP(B55,'22a'!$A:$A,'22a'!$G:$G,"pipino il breve") -> 107.57 | M55: =_xlfn.XLOOKUP(B55,'23a'!$A:$A,'23a'!$G:$G,"pipino il breve") -> 107.4 | N55: =_xlfn.XLOOKUP(B55,'24a'!$A:$A,'24a'!$G:$G,"pipino il breve") -> 108.06 | O55: 107.71 | R55: =_xlfn.XLOOKUP(B55,'28'!$A:$A,'28'!$G:$G,"pipino il breve") -> 107.61 | S55: =_xlfn.XLOOKUP(B55,'29'!$A:$A,'29'!$G:$G,"pipino il breve") -> 107.6 | T55: =_xlfn.XLOOKUP(B55,'30'!$A:$A,'30'!$G:$G,"pipino il breve") -> 107.92 | V55: =_xlfn.XLOOKUP(B55,'2'!$A:$A,'2'!$G:$G,"pipino il breve") -> 107.48 | Y55: =_xlfn.XLOOKUP(B55,'5'!$A:$A,'5'!$G:$G,"pipino il breve") -> 107.58 | Z55: =_xlfn.XLOOKUP(B55,'6'!$A:$A,'6'!$G:$G,"pipino il breve") -> 107.53 | AA55: =_xlfn.XLOOKUP(B55,'7'!$A:$A,'7'!$G:$G,"pipino il breve") -> 108 | AB55: =_xlfn.XLOOKUP(B55,'8'!$A:$A,'8'!$G:$G,"pipino il breve") -> 107.88 | AC55: =_xlfn.XLOOKUP(B55,'9'!$A:$A,'9'!$G:$G,"pipino il breve") -> 107.59 | AF55: =_xlfn.XLOOKUP(B55,'12'!$A:$A,'12'!$G:$G,"pipino il breve") -> 107.07 | AG55: =_xlfn.XLOOKUP(B55,'13'!$A:$A,'13'!$G:$G,"pipino il breve") -> 107 | AH55: =_xlfn.XLOOKUP(B55,'14'!$A:$A,'14'!$G:$G,"pipino il breve") -> 106.91 | AI55: =_xlfn.XLOOKUP(B55,'15'!$A:$A,'15'!$G:$G,"pipino il breve") -> 107.26
A56: 55 | B56: IT0005648149 | C56: 1.4951 | D56: 01/10/2035 | E56: =_xlfn.XLOOKUP(B56,'15a'!$A:$A,'15a'!$G:$G,"pipino il breve") -> 100.24 | F56: =_xlfn.XLOOKUP(B56,'16a'!$A:$A,'16a'!$G:$G,"pipino il breve") -> 100.24 | G56: =_xlfn.XLOOKUP(B56,'17a'!$A:$A,'17a'!$G:$G,"pipino il breve") -> 100.24 | L56: =_xlfn.XLOOKUP(B56,'22a'!$A:$A,'22a'!$G:$G,"pipino il breve") -> 100.24 | M56: =_xlfn.XLOOKUP(B56,'23a'!$A:$A,'23a'!$G:$G,"pipino il breve") -> 100.24 | N56: =_xlfn.XLOOKUP(B56,'24a'!$A:$A,'24a'!$G:$G,"pipino il breve") -> 100.24 | O56: 100.24 | R56: =_xlfn.XLOOKUP(B56,'28'!$A:$A,'28'!$G:$G,"pipino il breve") -> 100.24 | S56: =_xlfn.XLOOKUP(B56,'29'!$A:$A,'29'!$G:$G,"pipino il breve") -> 100.24 | T56: =_xlfn.XLOOKUP(B56,'30'!$A:$A,'30'!$G:$G,"pipino il breve") -> 100.24 | V56: =_xlfn.XLOOKUP(B56,'2'!$A:$A,'2'!$G:$G,"pipino il breve") -> 99.82 | Y56: =_xlfn.XLOOKUP(B56,'5'!$A:$A,'5'!$G:$G,"pipino il breve") -> 100.04 | Z56: =_xlfn.XLOOKUP(B56,'6'!$A:$A,'6'!$G:$G,"pipino il breve") -> 99.87 | AA56: =_xlfn.XLOOKUP(B56,'7'!$A:$A,'7'!$G:$G,"pipino il breve") -> 100.4 | AB56: =_xlfn.XLOOKUP(B56,'8'!$A:$A,'8'!$G:$G,"pipino il breve") -> 100.31 | AC56: =_xlfn.XLOOKUP(B56,'9'!$A:$A,'9'!$G:$G,"pipino il breve") -> 99.99 | AF56: =_xlfn.XLOOKUP(B56,'12'!$A:$A,'12'!$G:$G,"pipino il breve") -> 99.45 | AG56: =_xlfn.XLOOKUP(B56,'13'!$A:$A,'13'!$G:$G,"pipino il breve") -> 99.26 | AH56: =_xlfn.XLOOKUP(B56,'14'!$A:$A,'14'!$G:$G,"pipino il breve") -> 99.17 | AI56: =_xlfn.XLOOKUP(B56,'15'!$A:$A,'15'!$G:$G,"pipino il breve") -> 99.73
A57: 56 | B57: IT0005611055 | C57: 1.5 | D57: 01/10/2029 | E57: =_xlfn.XLOOKUP(B57,'15a'!$A:$A,'15a'!$G:$G,"pipino il breve") -> 101.33 | F57: =_xlfn.XLOOKUP(B57,'16a'!$A:$A,'16a'!$G:$G,"pipino il breve") -> 101.51 | G57: =_xlfn.XLOOKUP(B57,'17a'!$A:$A,'17a'!$G:$G,"pipino il breve") -> 101.79 | L57: =_xlfn.XLOOKUP(B57,'22a'!$A:$A,'22a'!$G:$G,"pipino il breve") -> 101.89 | M57: =_xlfn.XLOOKUP(B57,'23a'!$A:$A,'23a'!$G:$G,"pipino il breve") -> 101.74 | N57: =_xlfn.XLOOKUP(B57,'24a'!$A:$A,'24a'!$G:$G,"pipino il breve") -> 102.14 | O57: 101.88 | R57: =_xlfn.XLOOKUP(B57,'28'!$A:$A,'28'!$G:$G,"pipino il breve") -> 101.87 | S57: =_xlfn.XLOOKUP(B57,'29'!$A:$A,'29'!$G:$G,"pipino il breve") -> 101.85 | T57: =_xlfn.XLOOKUP(B57,'30'!$A:$A,'30'!$G:$G,"pipino il breve") -> 102.04 | V57: =_xlfn.XLOOKUP(B57,'2'!$A:$A,'2'!$G:$G,"pipino il breve") -> 101.81 | Y57: =_xlfn.XLOOKUP(B57,'5'!$A:$A,'5'!$G:$G,"pipino il breve") -> 101.87 | Z57: =_xlfn.XLOOKUP(B57,'6'!$A:$A,'6'!$G:$G,"pipino il breve") -> 101.82 | AA57: =_xlfn.XLOOKUP(B57,'7'!$A:$A,'7'!$G:$G,"pipino il breve") -> 101.96 | AB57: =_xlfn.XLOOKUP(B57,'8'!$A:$A,'8'!$G:$G,"pipino il breve") -> 101.94 | AC57: =_xlfn.XLOOKUP(B57,'9'!$A:$A,'9'!$G:$G,"pipino il breve") -> 101.81 | AF57: =_xlfn.XLOOKUP(B57,'12'!$A:$A,'12'!$G:$G,"pipino il breve") -> 101.38 | AG57: =_xlfn.XLOOKUP(B57,'13'!$A:$A,'13'!$G:$G,"pipino il breve") -> 101.32 | AH57: =_xlfn.XLOOKUP(B57,'14'!$A:$A,'14'!$G:$G,"pipino il breve") -> 101.27 | AI57: =_xlfn.XLOOKUP(B57,'15'!$A:$A,'15'!$G:$G,"pipino il breve") -> 101.52
A58: 57 | B58: IT0005566408 | C58: 2.05 | D58: 01/02/2029 | E58: =_xlfn.XLOOKUP(B58,'15a'!$A:$A,'15a'!$G:$G,"pipino il breve") -> 105.73 | F58: =_xlfn.XLOOKUP(B58,'16a'!$A:$A,'16a'!$G:$G,"pipino il breve") -> 105.87 | G58: =_xlfn.XLOOKUP(B58,'17a'!$A:$A,'17a'!$G:$G,"pipino il breve") -> 106.1 | L58: =_xlfn.XLOOKUP(B58,'22a'!$A:$A,'22a'!$G:$G,"pipino il breve") -> 106.16 | M58: =_xlfn.XLOOKUP(B58,'23a'!$A:$A,'23a'!$G:$G,"pipino il breve") -> 106.03 | N58: =_xlfn.XLOOKUP(B58,'24a'!$A:$A,'24a'!$G:$G,"pipino il breve") -> 106.36 | O58: 106.15 | R58: =_xlfn.XLOOKUP(B58,'28'!$A:$A,'28'!$G:$G,"pipino il breve") -> 106.21 | S58: =_xlfn.XLOOKUP(B58,'29'!$A:$A,'29'!$G:$G,"pipino il breve") -> 106.13 | T58: =_xlfn.XLOOKUP(B58,'30'!$A:$A,'30'!$G:$G,"pipino il breve") -> 106.2 | V58: =_xlfn.XLOOKUP(B58,'2'!$A:$A,'2'!$G:$G,"pipino il breve") -> 106.06 | Y58: =_xlfn.XLOOKUP(B58,'5'!$A:$A,'5'!$G:$G,"pipino il breve") -> 106.08 | Z58: =_xlfn.XLOOKUP(B58,'6'!$A:$A,'6'!$G:$G,"pipino il breve") -> 106.08 | AA58: =_xlfn.XLOOKUP(B58,'7'!$A:$A,'7'!$G:$G,"pipino il breve") -> 106.26 | AB58: =_xlfn.XLOOKUP(B58,'8'!$A:$A,'8'!$G:$G,"pipino il breve") -> 106.09 | AC58: =_xlfn.XLOOKUP(B58,'9'!$A:$A,'9'!$G:$G,"pipino il breve") -> 105.96 | AF58: =_xlfn.XLOOKUP(B58,'12'!$A:$A,'12'!$G:$G,"pipino il breve") -> 105.62 | AG58: =_xlfn.XLOOKUP(B58,'13'!$A:$A,'13'!$G:$G,"pipino il breve") -> 105.58 | AH58: =_xlfn.XLOOKUP(B58,'14'!$A:$A,'14'!$G:$G,"pipino il breve") -> 105.52 | AI58: =_xlfn.XLOOKUP(B58,'15'!$A:$A,'15'!$G:$G,"pipino il breve") -> 105.72
A59: 58 | B59: IT0005637399 | C59: 0.9779 | D59: 01/07/2030 | E59: =_xlfn.XLOOKUP(B59,'15a'!$A:$A,'15a'!$G:$G,"pipino il breve") -> 100.38 | F59: =_xlfn.XLOOKUP(B59,'16a'!$A:$A,'16a'!$G:$G,"pipino il breve") -> 100.58 | G59: =_xlfn.XLOOKUP(B59,'17a'!$A:$A,'17a'!$G:$G,"pipino il breve") -> 100.9 | L59: =_xlfn.XLOOKUP(B59,'22a'!$A:$A,'22a'!$G:$G,"pipino il breve") -> 100.97 | M59: =_xlfn.XLOOKUP(B59,'23a'!$A:$A,'23a'!$G:$G,"pipino il breve") -> 100.8 | N59: =_xlfn.XLOOKUP(B59,'24a'!$A:$A,'24a'!$G:$G,"pipino il breve") -> 101.3 | O59: 101.06 | R59: =_xlfn.XLOOKUP(B59,'28'!$A:$A,'28'!$G:$G,"pipino il breve") -> 101.02 | S59: =_xlfn.XLOOKUP(B59,'29'!$A:$A,'29'!$G:$G,"pipino il breve") -> 101.02 | T59: =_xlfn.XLOOKUP(B59,'30'!$A:$A,'30'!$G:$G,"pipino il breve") -> 101.24 | V59: =_xlfn.XLOOKUP(B59,'2'!$A:$A,'2'!$G:$G,"pipino il breve") -> 100.97 | Y59: =_xlfn.XLOOKUP(B59,'5'!$A:$A,'5'!$G:$G,"pipino il breve") -> 101.02 | Z59: =_xlfn.XLOOKUP(B59,'6'!$A:$A,'6'!$G:$G,"pipino il breve") -> 100.99 | AA59: =_xlfn.XLOOKUP(B59,'7'!$A:$A,'7'!$G:$G,"pipino il breve") -> 101.26 | AB59: =_xlfn.XLOOKUP(B59,'8'!$A:$A,'8'!$G:$G,"pipino il breve") -> 101.17 | AC59: =_xlfn.XLOOKUP(B59,'9'!$A:$A,'9'!$G:$G,"pipino il breve") -> 100.97 | AF59: =_xlfn.XLOOKUP(B59,'12'!$A:$A,'12'!$G:$G,"pipino il breve") -> 100.57 | AG59: =_xlfn.XLOOKUP(B59,'13'!$A:$A,'13'!$G:$G,"pipino il breve") -> 100.48 | AH59: =_xlfn.XLOOKUP(B59,'14'!$A:$A,'14'!$G:$G,"pipino il breve") -> 100.43 | AI59: =_xlfn.XLOOKUP(B59,'15'!$A:$A,'15'!$G:$G,"pipino il breve") -> 100.74
A60: 59 | B60: IT0005494239 | C60: 1.25 | D60: 01/12/2032 | E60: =_xlfn.XLOOKUP(B60,'15a'!$A:$A,'15a'!$G:$G,"pipino il breve") -> 94.76 | F60: =_xlfn.XLOOKUP(B60,'16a'!$A:$A,'16a'!$G:$G,"pipino il breve") -> 95.05 | G60: =_xlfn.XLOOKUP(B60,'17a'!$A:$A,'17a'!$G:$G,"pipino il breve") -> 95.4 | L60: =_xlfn.XLOOKUP(B60,'22a'!$A:$A,'22a'!$G:$G,"pipino il breve") -> 95.56 | M60: =_xlfn.XLOOKUP(B60,'23a'!$A:$A,'23a'!$G:$G,"pipino il breve") -> 95.44 | N60: =_xlfn.XLOOKUP(B60,'24a'!$A:$A,'24a'!$G:$G,"pipino il breve") -> 96.05 | O60: 95.77 | R60: =_xlfn.XLOOKUP(B60,'28'!$A:$A,'28'!$G:$G,"pipino il breve") -> 95.65 | S60: =_xlfn.XLOOKUP(B60,'29'!$A:$A,'29'!$G:$G,"pipino il breve") -> 95.73 | T60: =_xlfn.XLOOKUP(B60,'30'!$A:$A,'30'!$G:$G,"pipino il breve") -> 95.91 | V60: =_xlfn.XLOOKUP(B60,'2'!$A:$A,'2'!$G:$G,"pipino il breve") -> 95.61 | Y60: =_xlfn.XLOOKUP(B60,'5'!$A:$A,'5'!$G:$G,"pipino il breve") -> 95.7 | Z60: =_xlfn.XLOOKUP(B60,'6'!$A:$A,'6'!$G:$G,"pipino il breve") -> 95.63 | AA60: =_xlfn.XLOOKUP(B60,'7'!$A:$A,'7'!$G:$G,"pipino il breve") -> 96.04 | AB60: =_xlfn.XLOOKUP(B60,'8'!$A:$A,'8'!$G:$G,"pipino il breve") -> 95.91 | AC60: =_xlfn.XLOOKUP(B60,'9'!$A:$A,'9'!$G:$G,"pipino il breve") -> 95.69 | AF60: =_xlfn.XLOOKUP(B60,'12'!$A:$A,'12'!$G:$G,"pipino il breve") -> 95.2 | AG60: =_xlfn.XLOOKUP(B60,'13'!$A:$A,'13'!$G:$G,"pipino il breve") -> 95.05 | AH60: =_xlfn.XLOOKUP(B60,'14'!$A:$A,'14'!$G:$G,"pipino il breve") -> 94.96 | AI60: =_xlfn.XLOOKUP(B60,'15'!$A:$A,'15'!$G:$G,"pipino il breve") -> 95.4
A61: 60 | B61: IT0005274805 | C61: 1.025 | D61: 01/08/2027 | E61: =_xlfn.XLOOKUP(B61,'15a'!$A:$A,'15a'!$G:$G,"pipino il breve") -> 99.96 | F61: =_xlfn.XLOOKUP(B61,'16a'!$A:$A,'16a'!$G:$G,"pipino il breve") -> 100.08 | G61: =_xlfn.XLOOKUP(B61,'17a'!$A:$A,'17a'!$G:$G,"pipino il breve") -> 100.18 | L61: =_xlfn.XLOOKUP(B61,'22a'!$A:$A,'22a'!$G:$G,"pipino il breve") -> 100.25 | M61: =_xlfn.XLOOKUP(B61,'23a'!$A:$A,'23a'!$G:$G,"pipino il breve") -> 100.15 | N61: =_xlfn.XLOOKUP(B61,'24a'!$A:$A,'24a'!$G:$G,"pipino il breve") -> 100.3 | O61: 100.2 | R61: =_xlfn.XLOOKUP(B61,'28'!$A:$A,'28'!$G:$G,"pipino il breve") -> 100.25 | S61: =_xlfn.XLOOKUP(B61,'29'!$A:$A,'29'!$G:$G,"pipino il breve") -> 100.2 | T61: =_xlfn.XLOOKUP(B61,'30'!$A:$A,'30'!$G:$G,"pipino il breve") -> 100.26 | V61: =_xlfn.XLOOKUP(B61,'2'!$A:$A,'2'!$G:$G,"pipino il breve") -> 100.2 | Y61: =_xlfn.XLOOKUP(B61,'5'!$A:$A,'5'!$G:$G,"pipino il breve") -> 100.2 | Z61: =_xlfn.XLOOKUP(B61,'6'!$A:$A,'6'!$G:$G,"pipino il breve") -> 100.2 | AA61: =_xlfn.XLOOKUP(B61,'7'!$A:$A,'7'!$G:$G,"pipino il breve") -> 100.3 | AB61: =_xlfn.XLOOKUP(B61,'8'!$A:$A,'8'!$G:$G,"pipino il breve") -> 100.19 | AC61: =_xlfn.XLOOKUP(B61,'9'!$A:$A,'9'!$G:$G,"pipino il breve") -> 100.16 | AF61: =_xlfn.XLOOKUP(B61,'12'!$A:$A,'12'!$G:$G,"pipino il breve") -> 99.9 | AG61: =_xlfn.XLOOKUP(B61,'13'!$A:$A,'13'!$G:$G,"pipino il breve") -> 99.89 | AH61: =_xlfn.XLOOKUP(B61,'14'!$A:$A,'14'!$G:$G,"pipino il breve") -> 99.86 | AI61: =_xlfn.XLOOKUP(B61,'15'!$A:$A,'15'!$G:$G,"pipino il breve") -> 99.98
A62: 61 | B62: IT0005500068 | C62: 1.325 | D62: 01/12/2027 | E62: =_xlfn.XLOOKUP(B62,'15a'!$A:$A,'15a'!$G:$G,"pipino il breve") -> 101.2 | F62: =_xlfn.XLOOKUP(B62,'16a'!$A:$A,'16a'!$G:$G,"pipino il breve") -> 101.32 | G62: =_xlfn.XLOOKUP(B62,'17a'!$A:$A,'17a'!$G:$G,"pipino il breve") -> 101.41 | L62: =_xlfn.XLOOKUP(B62,'22a'!$A:$A,'22a'!$G:$G,"pipino il breve") -> 101.55 | M62: =_xlfn.XLOOKUP(B62,'23a'!$A:$A,'23a'!$G:$G,"pipino il breve") -> 101.4 | N62: =_xlfn.XLOOKUP(B62,'24a'!$A:$A,'24a'!$G:$G,"pipino il breve") -> 101.61 | O62: 101.47 | R62: =_xlfn.XLOOKUP(B62,'28'!$A:$A,'28'!$G:$G,"pipino il breve") -> 101.52 | S62: =_xlfn.XLOOKUP(B62,'29'!$A:$A,'29'!$G:$G,"pipino il breve") -> 101.43 | T62: =_xlfn.XLOOKUP(B62,'30'!$A:$A,'30'!$G:$G,"pipino il breve") -> 101.5 | V62: =_xlfn.XLOOKUP(B62,'2'!$A:$A,'2'!$G:$G,"pipino il breve") -> 101.41 | Y62: =_xlfn.XLOOKUP(B62,'5'!$A:$A,'5'!$G:$G,"pipino il breve") -> 101.41 | Z62: =_xlfn.XLOOKUP(B62,'6'!$A:$A,'6'!$G:$G,"pipino il breve") -> 101.45 | AA62: =_xlfn.XLOOKUP(B62,'7'!$A:$A,'7'!$G:$G,"pipino il breve") -> 101.52 | AB62: =_xlfn.XLOOKUP(B62,'8'!$A:$A,'8'!$G:$G,"pipino il breve") -> 101.43 | AC62: =_xlfn.XLOOKUP(B62,'9'!$A:$A,'9'!$G:$G,"pipino il breve") -> 101.38 | AF62: =_xlfn.XLOOKUP(B62,'12'!$A:$A,'12'!$G:$G,"pipino il breve") -> 101.06 | AG62: =_xlfn.XLOOKUP(B62,'13'!$A:$A,'13'!$G:$G,"pipino il breve") -> 101.06 | AH62: =_xlfn.XLOOKUP(B62,'14'!$A:$A,'14'!$G:$G,"pipino il breve") -> 101.05 | AI62: =_xlfn.XLOOKUP(B62,'15'!$A:$A,'15'!$G:$G,"pipino il breve") -> 101.14
A63: 62 | B63: IT0005162828 | C63: 1.35 | D63: 01/03/2047 | E63: =_xlfn.XLOOKUP(B63,'15a'!$A:$A,'15a'!$G:$G,"pipino il breve") -> 78.85 | F63: =_xlfn.XLOOKUP(B63,'16a'!$A:$A,'16a'!$G:$G,"pipino il breve") -> 78.76 | G63: =_xlfn.XLOOKUP(B63,'17a'!$A:$A,'17a'!$G:$G,"pipino il breve") -> 79.01 | L63: =_xlfn.XLOOKUP(B63,'22a'!$A:$A,'22a'!$G:$G,"pipino il breve") -> 79.43 | M63: =_xlfn.XLOOKUP(B63,'23a'!$A:$A,'23a'!$G:$G,"pipino il breve") -> 79.16 | N63: =_xlfn.XLOOKUP(B63,'24a'!$A:$A,'24a'!$G:$G,"pipino il breve") -> 80.06 | O63: 79.62 | R63: =_xlfn.XLOOKUP(B63,'28'!$A:$A,'28'!$G:$G,"pipino il breve") -> 79.42 | S63: =_xlfn.XLOOKUP(B63,'29'!$A:$A,'29'!$G:$G,"pipino il breve") -> 79.38 | T63: =_xlfn.XLOOKUP(B63,'30'!$A:$A,'30'!$G:$G,"pipino il breve") -> 79.72 | V63: =_xlfn.XLOOKUP(B63,'2'!$A:$A,'2'!$G:$G,"pipino il breve") -> 79.14 | Y63: =_xlfn.XLOOKUP(B63,'5'!$A:$A,'5'!$G:$G,"pipino il breve") -> 79.24 | Z63: =_xlfn.XLOOKUP(B63,'6'!$A:$A,'6'!$G:$G,"pipino il breve") -> 78.86 | AA63: =_xlfn.XLOOKUP(B63,'7'!$A:$A,'7'!$G:$G,"pipino il breve") -> 79.78 | AB63: =_xlfn.XLOOKUP(B63,'8'!$A:$A,'8'!$G:$G,"pipino il breve") -> 79.48 | AC63: =_xlfn.XLOOKUP(B63,'9'!$A:$A,'9'!$G:$G,"pipino il breve") -> 79.08 | AF63: =_xlfn.XLOOKUP(B63,'12'!$A:$A,'12'!$G:$G,"pipino il breve") -> 78.59 | AG63: =_xlfn.XLOOKUP(B63,'13'!$A:$A,'13'!$G:$G,"pipino il breve") -> 78.24 | AH63: =_xlfn.XLOOKUP(B63,'14'!$A:$A,'14'!$G:$G,"pipino il breve") -> 78.2 | AI63: =_xlfn.XLOOKUP(B63,'15'!$A:$A,'15'!$G:$G,"pipino il breve") -> 78.99
A64: 63 | B64: IT0005433195 | C64: 0.475 | D64: 01/03/2037 | E64: =_xlfn.XLOOKUP(B64,'15a'!$A:$A,'15a'!$G:$G,"pipino il breve") -> 73.01 | F64: =_xlfn.XLOOKUP(B64,'16a'!$A:$A,'16a'!$G:$G,"pipino il breve") -> 73.24 | G64: =_xlfn.XLOOKUP(B64,'17a'!$A:$A,'17a'!$G:$G,"pipino il breve") -> 73.58 | L64: =_xlfn.XLOOKUP(B64,'22a'!$A:$A,'22a'!$G:$G,"pipino il breve") -> 73.81 | M64: =_xlfn.XLOOKUP(B64,'23a'!$A:$A,'23a'!$G:$G,"pipino il breve") -> 73.68 | N64: =_xlfn.XLOOKUP(B64,'24a'!$A:$A,'24a'!$G:$G,"pipino il breve") -> 74.37 | O64: 73.98 | R64: =_xlfn.XLOOKUP(B64,'28'!$A:$A,'28'!$G:$G,"pipino il breve") -> 73.81 | S64: =_xlfn.XLOOKUP(B64,'29'!$A:$A,'29'!$G:$G,"pipino il breve") -> 73.85 | T64: =_xlfn.XLOOKUP(B64,'30'!$A:$A,'30'!$G:$G,"pipino il breve") -> 74.12 | V64: =_xlfn.XLOOKUP(B64,'2'!$A:$A,'2'!$G:$G,"pipino il breve") -> 73.76 | Y64: =_xlfn.XLOOKUP(B64,'5'!$A:$A,'5'!$G:$G,"pipino il breve") -> 73.81 | Z64: =_xlfn.XLOOKUP(B64,'6'!$A:$A,'6'!$G:$G,"pipino il breve") -> 73.8 | AA64: =_xlfn.XLOOKUP(B64,'7'!$A:$A,'7'!$G:$G,"pipino il breve") -> 74.3 | AB64: =_xlfn.XLOOKUP(B64,'8'!$A:$A,'8'!$G:$G,"pipino il breve") -> 74.13 | AC64: =_xlfn.XLOOKUP(B64,'9'!$A:$A,'9'!$G:$G,"pipino il breve") -> 73.93 | AF64: =_xlfn.XLOOKUP(B64,'12'!$A:$A,'12'!$G:$G,"pipino il breve") -> 73.49 | AG64: =_xlfn.XLOOKUP(B64,'13'!$A:$A,'13'!$G:$G,"pipino il breve") -> 73.25 | AH64: =_xlfn.XLOOKUP(B64,'14'!$A:$A,'14'!$G:$G,"pipino il breve") -> 73.12 | AI64: =_xlfn.XLOOKUP(B64,'15'!$A:$A,'15'!$G:$G,"pipino il breve") -> 73.79
A65: 64 | B65: IT0005480980 | C65: 1.075 | D65: 01/09/2052 | E65: =_xlfn.XLOOKUP(B65,'15a'!$A:$A,'15a'!$G:$G,"pipino il breve") -> 66.12 | F65: =_xlfn.XLOOKUP(B65,'16a'!$A:$A,'16a'!$G:$G,"pipino il breve") -> 65.93 | G65: =_xlfn.XLOOKUP(B65,'17a'!$A:$A,'17a'!$G:$G,"pipino il breve") -> 66.25 | L65: =_xlfn.XLOOKUP(B65,'22a'!$A:$A,'22a'!$G:$G,"pipino il breve") -> 66.62 | M65: =_xlfn.XLOOKUP(B65,'23a'!$A:$A,'23a'!$G:$G,"pipino il breve") -> 66.37 | N65: =_xlfn.XLOOKUP(B65,'24a'!$A:$A,'24a'!$G:$G,"pipino il breve") -> 67.2 | O65: 66.8 | R65: =_xlfn.XLOOKUP(B65,'28'!$A:$A,'28'!$G:$G,"pipino il breve") -> 66.61 | S65: =_xlfn.XLOOKUP(B65,'29'!$A:$A,'29'!$G:$G,"pipino il breve") -> 66.47 | T65: =_xlfn.XLOOKUP(B65,'30'!$A:$A,'30'!$G:$G,"pipino il breve") -> 67 | V65: =_xlfn.XLOOKUP(B65,'2'!$A:$A,'2'!$G:$G,"pipino il breve") -> 66.35 | Y65: =_xlfn.XLOOKUP(B65,'5'!$A:$A,'5'!$G:$G,"pipino il breve") -> 66.34 | Z65: =_xlfn.XLOOKUP(B65,'6'!$A:$A,'6'!$G:$G,"pipino il breve") -> 66.08 | AA65: =_xlfn.XLOOKUP(B65,'7'!$A:$A,'7'!$G:$G,"pipino il breve") -> 67.03 | AB65: =_xlfn.XLOOKUP(B65,'8'!$A:$A,'8'!$G:$G,"pipino il breve") -> 66.69 | AC65: =_xlfn.XLOOKUP(B65,'9'!$A:$A,'9'!$G:$G,"pipino il breve") -> 66.29 | AF65: =_xlfn.XLOOKUP(B65,'12'!$A:$A,'12'!$G:$G,"pipino il breve") -> 65.92 | AG65: =_xlfn.XLOOKUP(B65,'13'!$A:$A,'13'!$G:$G,"pipino il breve") -> 65.4 | AH65: =_xlfn.XLOOKUP(B65,'14'!$A:$A,'14'!$G:$G,"pipino il breve") -> 65.44 | AI65: =_xlfn.XLOOKUP(B65,'15'!$A:$A,'15'!$G:$G,"pipino il breve") -> 66.21
... A110: 109 | B110: IT0005647273 | C110: 1.275 | D110: 15/05/2056 | E110: =_xlfn.XLOOKUP(B110,'15a'!$A:$A,'15a'!$G:$G,"pipino il breve") -> 100.6 | F110: =_xlfn.XLOOKUP(B110,'16a'!$A:$A,'16a'!$G:$G,"pipino il breve") -> 100.6 | G110: =_xlfn.XLOOKUP(B110,'17a'!$A:$A,'17a'!$G:$G,"pipino il breve") -> 100.6 | L110: =_xlfn.XLOOKUP(B110,'22a'!$A:$A,'22a'!$G:$G,"pipino il breve") -> 100.6 | M110: =_xlfn.XLOOKUP(B110,'23a'!$A:$A,'23a'!$G:$G,"pipino il breve") -> 100.6 | N110: =_xlfn.XLOOKUP(B110,'24a'!$A:$A,'24a'!$G:$G,"pipino il breve") -> 101.76 | O110: 101.64 | R110: =_xlfn.XLOOKUP(B110,'28'!$A:$A,'28'!$G:$G,"pipino il breve") -> 100.85 | S110: =_xlfn.XLOOKUP(B110,'29'!$A:$A,'29'!$G:$G,"pipino il breve") -> 100.2 | T110: =_xlfn.XLOOKUP(B110,'30'!$A:$A,'30'!$G:$G,"pipino il breve") -> 100.86 | V110: =_xlfn.XLOOKUP(B110,'2'!$A:$A,'2'!$G:$G,"pipino il breve") -> 100.6 | Y110: =_xlfn.XLOOKUP(B110,'5'!$A:$A,'5'!$G:$G,"pipino il breve") -> 100.43 | Z110: =_xlfn.XLOOKUP(B110,'6'!$A:$A,'6'!$G:$G,"pipino il breve") -> 99.85 | AA110: =_xlfn.XLOOKUP(B110,'7'!$A:$A,'7'!$G:$G,"pipino il breve") -> 101.5 | AB110: =_xlfn.XLOOKUP(B110,'8'!$A:$A,'8'!$G:$G,"pipino il breve") -> 101.45 | AC110: =_xlfn.XLOOKUP(B110,'9'!$A:$A,'9'!$G:$G,"pipino il breve") -> 100.75 | AF110: =_xlfn.XLOOKUP(B110,'12'!$A:$A,'12'!$G:$G,"pipino il breve") -> 100.94 | AG110: =_xlfn.XLOOKUP(B110,'13'!$A:$A,'13'!$G:$G,"pipino il breve") -> 100.55 | AH110: =_xlfn.XLOOKUP(B110,'14'!$A:$A,'14'!$G:$G,"pipino il breve") -> 100.69 | AI110: =_xlfn.XLOOKUP(B110,'15'!$A:$A,'15'!$G:$G,"pipino il breve") -> 101.33

Sheet maggio
A1: ID | B1: ISIN | C1: Coupon | D1: Maturity | E1: 45772 | F1: 45773 | G1: 45774 | H1: 45775 | I1: 45776 | J1: 45777 | K1: 45778 | L1: 45779 | M1: 45780 | N1: 45781 | O1: 45782 | P1: 45783 | Q1: 45784 | R1: 45785 | S1: 45786 | T1: 45787 | U1: 45788 | V1: 45789 | W1: 45790 | X1: 45791 | Y1: 45792 | Z1: 45793 | AA1: 45794 | AB1: 45795 | AC1: 45796 | AD1: 45797 | AE1: 45798 | AF1: 45799 | AG1: 45800 | AH1: 45801 | AI1: 45802 | AJ1: 45803 | AK1: 45804
A2: 1 | B2: IT0003256820 | C2: 2.875 | D2: 01/02/2033 | E2: 117.52 | F2: 117.52 | G2: 117.52 | H2: =_xlfn.XLOOKUP(B2,'28'!$A:$A,'28'!$G:$G,"pipino il breve") -> 117.4 | I2: =_xlfn.XLOOKUP(B2,'29'!$A:$A,'29'!$G:$G,"pipino il breve") -> 117.36 | J2: =_xlfn.XLOOKUP(B2,'30'!$A:$A,'30'!$G:$G,"pipino il breve") -> 117.71 | K2: =_xlfn.XLOOKUP(B2,'30'!$A:$A,'30'!$G:$G,"pipino il breve") -> 117.71 | L2: =_xlfn.XLOOKUP(B2,'2'!$A:$A,'2'!$G:$G,"pipino il breve") -> 117.24 | M2: =_xlfn.XLOOKUP(B2,'2'!$A:$A,'2'!$G:$G,"pipino il breve") -> 117.24 | N2: =_xlfn.XLOOKUP(B2,'2'!$A:$A,'2'!$G:$G,"pipino il breve") -> 117.24 | O2: =_xlfn.XLOOKUP(B2,'5'!$A:$A,'5'!$G:$G,"pipino il breve") -> 117.4 | P2: =_xlfn.XLOOKUP(B2,'6'!$A:$A,'6'!$G:$G,"pipino il breve") -> 117.25 | Q2: =_xlfn.XLOOKUP(B2,'7'!$A:$A,'7'!$G:$G,"pipino il breve") -> 117.67 | R2: =_xlfn.XLOOKUP(B2,'8'!$A:$A,'8'!$G:$G,"pipino il breve") -> 117.56 | S2: =_xlfn.XLOOKUP(B2,'9'!$A:$A,'9'!$G:$G,"pipino il breve") -> 117.32 | T2: =_xlfn.XLOOKUP(B2,'9'!$A:$A,'9'!$G:$G,"pipino il breve") -> 117.32 | U2: =_xlfn.XLOOKUP(B2,'9'!$A:$A,'9'!$G:$G,"pipino il breve") -> 117.32 | V2: =_xlfn.XLOOKUP(B2,'12'!$A:$A,'12'!$G:$G,"pipino il breve") -> 116.74 | W2: =_xlfn.XLOOKUP(B2,'13'!$A:$A,'13'!$G:$G,"pipino il breve") -> 116.59 | X2: =_xlfn.XLOOKUP(B2,'14'!$A:$A,'14'!$G:$G,"pipino il breve") -> 116.5 | Y2: =_xlfn.XLOOKUP(B2,'15'!$A:$A,'15'!$G:$G,"pipino il breve") -> 116.98 | Z2: =_xlfn.XLOOKUP(B2,'16'!$A:$A,'16'!$G:$G,"pipino il breve") -> 117.27 | AA2: =_xlfn.XLOOKUP(B2,'16'!$A:$A,'16'!$G:$G,"pipino il breve") -> 117.27 | AB2: =_xlfn.XLOOKUP(B2,'16'!$A:$A,'16'!$G:$G,"pipino il breve") -> 117.27 | AC2: =_xlfn.XLOOKUP(B2,'19'!$A:$A,'19'!$G:$G,"pipino il breve") -> 117.35 | AD2: =_xlfn.XLOOKUP(B2,'20'!$A:$A,'20'!$G:$G,"pipino il breve") -> 117.17 | AE2: =_xlfn.XLOOKUP(B2,'21'!$A:$A,'21'!$G:$G,"pipino il breve") -> 117.09 | AF2: =_xlfn.XLOOKUP(B2,'22'!$A:$A,'22'!$G:$G,"pipino il breve") -> 116.94 | AG2: =_xlfn.XLOOKUP(B2,'23'!$A:$A,'23'!$G:$G,"pipino il breve") -> 117.38 | AH2: =_xlfn.XLOOKUP(B2,'23'!$A:$A,'23'!$G:$G,"pipino il breve") -> 117.38 | AI2: =_xlfn.XLOOKUP(B2,'23'!$A:$A,'23'!$G:$G,"pipino il breve") -> 117.38 | AJ2: =_xlfn.XLOOKUP(B2,'26'!$A:$A,'26'!$G:$G,"pipino il breve") -> 117.61 | AK2: =_xlfn.XLOOKUP(B2,'27'!$A:$A,'27'!$G:$G,"pipino il breve") -> 117.71
A3: 2 | B3: IT0005240830 | C3: 1.1 | D3: 01/06/2027 | E3: 100.58 | F3: 100.58 | G3: 100.58 | H3: =_xlfn.XLOOKUP(B3,'28'!$A:$A,'28'!$G:$G,"pipino il breve") -> 100.6 | I3: =_xlfn.XLOOKUP(B3,'29'!$A:$A,'29'!$G:$G,"pipino il breve") -> 100.57 | J3: =_xlfn.XLOOKUP(B3,'30'!$A:$A,'30'!$G:$G,"pipino il breve") -> 100.63 | K3: =_xlfn.XLOOKUP(B3,'30'!$A:$A,'30'!$G:$G,"pipino il breve") -> 100.63 | L3: =_xlfn.XLOOKUP(B3,'2'!$A:$A,'2'!$G:$G,"pipino il breve") -> 100.54 | M3: =_xlfn.XLOOKUP(B3,'2'!$A:$A,'2'!$G:$G,"pipino il breve") -> 100.54 | N3: =_xlfn.XLOOKUP(B3,'2'!$A:$A,'2'!$G:$G,"pipino il breve") -> 100.54 | O3: =_xlfn.XLOOKUP(B3,'5'!$A:$A,'5'!$G:$G,"pipino il breve") -> 100.54 | P3: =_xlfn.XLOOKUP(B3,'6'!$A:$A,'6'!$G:$G,"pipino il breve") -> 100.52 | Q3: =_xlfn.XLOOKUP(B3,'7'!$A:$A,'7'!$G:$G,"pipino il breve") -> 100.67 | R3: =_xlfn.XLOOKUP(B3,'8'!$A:$A,'8'!$G:$G,"pipino il breve") -> 100.56 | S3: =_xlfn.XLOOKUP(B3,'9'!$A:$A,'9'!$G:$G,"pipino il breve") -> 100.5 | T3: =_xlfn.XLOOKUP(B3,'9'!$A:$A,'9'!$G:$G,"pipino il breve") -> 100.5 | U3: =_xlfn.XLOOKUP(B3,'9'!$A:$A,'9'!$G:$G,"pipino il breve") -> 100.5 | V3: =_xlfn.XLOOKUP(B3,'12'!$A:$A,'12'!$G:$G,"pipino il breve") -> 100.29 | W3: =_xlfn.XLOOKUP(B3,'13'!$A:$A,'13'!$G:$G,"pipino il breve") -> 100.2 | X3: =_xlfn.XLOOKUP(B3,'14'!$A:$A,'14'!$G:$G,"pipino il breve") -> 100.28 | Y3: =_xlfn.XLOOKUP(B3,'15'!$A:$A,'15'!$G:$G,"pipino il breve") -> 100.37 | Z3: =_xlfn.XLOOKUP(B3,'16'!$A:$A,'16'!$G:$G,"pipino il breve") -> 100.4 | AA3: =_xlfn.XLOOKUP(B3,'16'!$A:$A,'16'!$G:$G,"pipino il breve") -> 100.4 | AB3: =_xlfn.XLOOKUP(B3,'16'!$A:$A,'16'!$G:$G,"pipino il breve") -> 100.4 | AC3: =_xlfn.XLOOKUP(B3,'19'!$A:$A,'19'!$G:$G,"pipino il breve") -> 100.44 | AD3: =_xlfn.XLOOKUP(B3,'20'!$A:$A,'20'!$G:$G,"pipino il breve") -> 100.41 | AE3: =_xlfn.XLOOKUP(B3,'21'!$A:$A,'21'!$G:$G,"pipino il breve") -> 100.4 | AF3: =_xlfn.XLOOKUP(B3,'22'!$A:$A,'22'!$G:$G,"pipino il breve") -> 100.43 | AG3: =_xlfn.XLOOKUP(B3,'23'!$A:$A,'23'!$G:$G,"pipino il breve") -> 100.69 | AH3: =_xlfn.XLOOKUP(B3,'23'!$A:$A,'23'!$G:$G,"pipino il breve") -> 100.69 | AI3: =_xlfn.XLOOKUP(B3,'23'!$A:$A,'23'!$G:$G,"pipino il breve") -> 100.69 | AJ3: =_xlfn.XLOOKUP(B3,'26'!$A:$A,'26'!$G:$G,"pipino il breve") -> 100.3 | AK3: =_xlfn.XLOOKUP(B3,'27'!$A:$A,'27'!$G:$G,"pipino il breve") -> 100.52
A4: 3 | B4: IT0005323032 | C4: 1 | D4: 01/02/2028 | E4: 99.79 | F4: 99.79 | G4: 99.79 | H4: =_xlfn.XLOOKUP(B4,'28'!$A:$A,'28'!$G:$G,"pipino il breve") -> 99.87 | I4: =_xlfn.XLOOKUP(B4,'29'!$A:$A,'29'!$G:$G,"pipino il breve") -> 99.85 | J4: =_xlfn.XLOOKUP(B4,'30'!$A:$A,'30'!$G:$G,"pipino il breve") -> 99.93 | K4: =_xlfn.XLOOKUP(B4,'30'!$A:$A,'30'!$G:$G,"pipino il breve") -> 99.93 | L4: =_xlfn.XLOOKUP(B4,'2'!$A:$A,'2'!$G:$G,"pipino il breve") -> 99.9 | M4: =_xlfn.XLOOKUP(B4,'2'!$A:$A,'2'!$G:$G,"pipino il breve") -> 99.9 | N4: =_xlfn.XLOOKUP(B4,'2'!$A:$A,'2'!$G:$G,"pipino il breve") -> 99.9 | O4: =_xlfn.XLOOKUP(B4,'5'!$A:$A,'5'!$G:$G,"pipino il breve") -> 99.82 | P4: =_xlfn.XLOOKUP(B4,'6'!$A:$A,'6'!$G:$G,"pipino il breve") -> 99.81 | Q4: =_xlfn.XLOOKUP(B4,'7'!$A:$A,'7'!$G:$G,"pipino il breve") -> 99.92 | R4: =_xlfn.XLOOKUP(B4,'8'!$A:$A,'8'!$G:$G,"pipino il breve") -> 99.84 | S4: =_xlfn.XLOOKUP(B4,'9'!$A:$A,'9'!$G:$G,"pipino il breve") -> 99.77 | T4: =_xlfn.XLOOKUP(B4,'9'!$A:$A,'9'!$G:$G,"pipino il breve") -> 99.77 | U4: =_xlfn.XLOOKUP(B4,'9'!$A:$A,'9'!$G:$G,"pipino il breve") -> 99.77 | V4: =_xlfn.XLOOKUP(B4,'12'!$A:$A,'12'!$G:$G,"pipino il breve") -> 99.47 | W4: =_xlfn.XLOOKUP(B4,'13'!$A:$A,'13'!$G:$G,"pipino il breve") -> 99.41 | X4: =_xlfn.XLOOKUP(B4,'14'!$A:$A,'14'!$G:$G,"pipino il breve") -> 99.45 | Y4: =_xlfn.XLOOKUP(B4,'15'!$A:$A,'15'!$G:$G,"pipino il breve") -> 99.5 | Z4: =_xlfn.XLOOKUP(B4,'16'!$A:$A,'16'!$G:$G,"pipino il breve") -> 99.66 | AA4: =_xlfn.XLOOKUP(B4,'16'!$A:$A,'16'!$G:$G,"pipino il breve") -> 99.66 | AB4: =_xlfn.XLOOKUP(B4,'16'!$A:$A,'16'!$G:$G,"pipino il breve") -> 99.66 | AC4: =_xlfn.XLOOKUP(B4,'19'!$A:$A,'19'!$G:$G,"pipino il breve") -> 99.71 | AD4: =_xlfn.XLOOKUP(B4,'20'!$A:$A,'20'!$G:$G,"pipino il breve") -> 99.71 | AE4: =_xlfn.XLOOKUP(B4,'21'!$A:$A,'21'!$G:$G,"pipino il breve") -> 99.64 | AF4: =_xlfn.XLOOKUP(B4,'22'!$A:$A,'22'!$G:$G,"pipino il breve") -> 99.68 | AG4: =_xlfn.XLOOKUP(B4,'23'!$A:$A,'23'!$G:$G,"pipino il breve") -> 99.82 | AH4: =_xlfn.XLOOKUP(B4,'23'!$A:$A,'23'!$G:$G,"pipino il breve") -> 99.82 | AI4: =_xlfn.XLOOKUP(B4,'23'!$A:$A,'23'!$G:$G,"pipino il breve") -> 99.82 | AJ4: =_xlfn.XLOOKUP(B4,'26'!$A:$A,'26'!$G:$G,"pipino il breve") -> 99.82 | AK4: =_xlfn.XLOOKUP(B4,'27'!$A:$A,'27'!$G:$G,"pipino il breve") -> 99.79
A5: 4 | B5: IT0005365165 | C5: 1.5 | D5: 01/08/2029 | E5: 102.36 | F5: 102.36 | G5: 102.36 | H5: =_xlfn.XLOOKUP(B5,'28'!$A:$A,'28'!$G:$G,"pipino il breve") -> 102.35 | I5: =_xlfn.XLOOKUP(B5,'29'!$A:$A,'29'!$G:$G,"pipino il breve") -> 102.28 | J5: =_xlfn.XLOOKUP(B5,'30'!$A:$A,'30'!$G:$G,"pipino il breve") -> 102.48 | K5: =_xlfn.XLOOKUP(B5,'30'!$A:$A,'30'!$G:$G,"pipino il breve") -> 102.48 | L5: =_xlfn.XLOOKUP(B5,'2'!$A:$A,'2'!$G:$G,"pipino il breve") -> 102.31 | M5: =_xlfn.XLOOKUP(B5,'2'!$A:$A,'2'!$G:$G,"pipino il breve") -> 102.31 | N5: =_xlfn.XLOOKUP(B5,'2'!$A:$A,'2'!$G:$G,"pipino il breve") -> 102.31 | O5: =_xlfn.XLOOKUP(B5,'5'!$A:$A,'5'!$G:$G,"pipino il breve") -> 102.3 | P5: =_xlfn.XLOOKUP(B5,'6'!$A:$A,'6'!$G:$G,"pipino il breve") -> 102.29 | Q5: =_xlfn.XLOOKUP(B5,'7'!$A:$A,'7'!$G:$G,"pipino il breve") -> 102.52 | R5: =_xlfn.XLOOKUP(B5,'8'!$A:$A,'8'!$G:$G,"pipino il breve") -> 102.23 | S5: =_xlfn.XLOOKUP(B5,'9'!$A:$A,'9'!$G:$G,"pipino il breve") -> 102.25 | T5: =_xlfn.XLOOKUP(B5,'9'!$A:$A,'9'!$G:$G,"pipino il breve") -> 102.25 | U5: =_xlfn.XLOOKUP(B5,'9'!$A:$A,'9'!$G:$G,"pipino il breve") -> 102.25 | V5: =_xlfn.XLOOKUP(B5,'12'!$A:$A,'12'!$G:$G,"pipino il breve") -> 101.84 | W5: =_xlfn.XLOOKUP(B5,'13'!$A:$A,'13'!$G:$G,"pipino il breve") -> 101.79 | X5: =_xlfn.XLOOKUP(B5,'14'!$A:$A,'14'!$G:$G,"pipino il breve") -> 101.77 | Y5: =_xlfn.XLOOKUP(B5,'15'!$A:$A,'15'!$G:$G,"pipino il breve") -> 102.29 | Z5: =_xlfn.XLOOKUP(B5,'16'!$A:$A,'16'!$G:$G,"pipino il breve") -> 102.17 | AA5: =_xlfn.XLOOKUP(B5,'16'!$A:$A,'16'!$G:$G,"pipino il breve") -> 102.17 | AB5: =_xlfn.XLOOKUP(B5,'16'!$A:$A,'16'!$G:$G,"pipino il breve") -> 102.17 | AC5: =_xlfn.XLOOKUP(B5,'19'!$A:$A,'19'!$G:$G,"pipino il breve") -> 102.16 | AD5: =_xlfn.XLOOKUP(B5,'20'!$A:$A,'20'!$G:$G,"pipino il breve") -> 102.11 | AE5: =_xlfn.XLOOKUP(B5,'21'!$A:$A,'21'!$G:$G,"pipino il breve") -> 102.04 | AF5: =_xlfn.XLOOKUP(B5,'22'!$A:$A,'22'!$G:$G,"pipino il breve") -> 102.05 | AG5: =_xlfn.XLOOKUP(B5,'23'!$A:$A,'23'!$G:$G,"pipino il breve") -> 102.28 | AH5: =_xlfn.XLOOKUP(B5,'23'!$A:$A,'23'!$G:$G,"pipino il breve") -> 102.28 | AI5: =_xlfn.XLOOKUP(B5,'23'!$A:$A,'23'!$G:$G,"pipino il breve") -> 102.28 | AJ5: =_xlfn.XLOOKUP(B5,'26'!$A:$A,'26'!$G:$G,"pipino il breve") -> 102.29 | AK5: =_xlfn.XLOOKUP(B5,'27'!$A:$A,'27'!$G:$G,"pipino il breve") -> 102.31
A6: 5 | B6: IT0005582421 | C6: 2.075 | D6: 01/10/2039 | E6: 102.48 | F6: 102.48 | G6: 102.48 | H6: =_xlfn.XLOOKUP(B6,'28'!$A:$A,'28'!$G:$G,"pipino il breve") -> 102.27 | I6: =_xlfn.XLOOKUP(B6,'29'!$A:$A,'29'!$G:$G,"pipino il breve") -> 102.21 | J6: =_xlfn.XLOOKUP(B6,'30'!$A:$A,'30'!$G:$G,"pipino il breve") -> 102.58 | K6: =_xlfn.XLOOKUP(B6,'30'!$A:$A,'30'!$G:$G,"pipino il breve") -> 102.58 | L6: =_xlfn.XLOOKUP(B6,'2'!$A:$A,'2'!$G:$G,"pipino il breve") -> 102.18 | M6: =_xlfn.XLOOKUP(B6,'2'!$A:$A,'2'!$G:$G,"pipino il breve") -> 102.18 | N6: =_xlfn.XLOOKUP(B6,'2'!$A:$A,'2'!$G:$G,"pipino il breve") -> 102.18 | O6: =_xlfn.XLOOKUP(B6,'5'!$A:$A,'5'!$G:$G,"pipino il breve") -> 102.15 | P6: =_xlfn.XLOOKUP(B6,'6'!$A:$A,'6'!$G:$G,"pipino il breve") -> 101.96 | Q6: =_xlfn.XLOOKUP(B6,'7'!$A:$A,'7'!$G:$G,"pipino il breve") -> 102.73 | R6: =_xlfn.XLOOKUP(B6,'8'!$A:$A,'8'!$G:$G,"pipino il breve") -> 102.5 | S6: =_xlfn.XLOOKUP(B6,'9'!$A:$A,'9'!$G:$G,"pipino il breve") -> 102.1 | T6: =_xlfn.XLOOKUP(B6,'9'!$A:$A,'9'!$G:$G,"pipino il breve") -> 102.1 | U6: =_xlfn.XLOOKUP(B6,'9'!$A:$A,'9'!$G:$G,"pipino il breve") -> 102.1 | V6: =_xlfn.XLOOKUP(B6,'12'!$A:$A,'12'!$G:$G,"pipino il breve") -> 101.61 | W6: =_xlfn.XLOOKUP(B6,'13'!$A:$A,'13'!$G:$G,"pipino il breve") -> 101.22 | X6: =_xlfn.XLOOKUP(B6,'14'!$A:$A,'14'!$G:$G,"pipino il breve") -> 101.24 | Y6: =_xlfn.XLOOKUP(B6,'15'!$A:$A,'15'!$G:$G,"pipino il breve") -> 101.99 | Z6: =_xlfn.XLOOKUP(B6,'16'!$A:$A,'16'!$G:$G,"pipino il breve") -> 102.46 | AA6: =_xlfn.XLOOKUP(B6,'16'!$A:$A,'16'!$G:$G,"pipino il breve") -> 102.46 | AB6: =_xlfn.XLOOKUP(B6,'16'!$A:$A,'16'!$G:$G,"pipino il breve") -> 102.46 | AC6: =_xlfn.XLOOKUP(B6,'19'!$A:$A,'19'!$G:$G,"pipino il breve") -> 102.41 | AD6: =_xlfn.XLOOKUP(B6,'20'!$A:$A,'20'!$G:$G,"pipino il breve") -> 102.12 | AE6: =_xlfn.XLOOKUP(B6,'21'!$A:$A,'21'!$G:$G,"pipino il breve") -> 101.84 | AF6: =_xlfn.XLOOKUP(B6,'22'!$A:$A,'22'!$G:$G,"pipino il breve") -> 101.59 | AG6: =_xlfn.XLOOKUP(B6,'23'!$A:$A,'23'!$G:$G,"pipino il breve") -> 102.03 | AH6: =_xlfn.XLOOKUP(B6,'23'!$A:$A,'23'!$G:$G,"pipino il breve") -> 102.03 | AI6: =_xlfn.XLOOKUP(B6,'23'!$A:$A,'23'!$G:$G,"pipino il breve") -> 102.03 | AJ6: =_xlfn.XLOOKUP(B6,'26'!$A:$A,'26'!$G:$G,"pipino il breve") -> 102.56 | AK6: =_xlfn.XLOOKUP(B6,'27'!$A:$A,'27'!$G:$G,"pipino il breve") -> 102.99
A7: 6 | B7: IT0005436693 | C7: 0.3 | D7: 01/08/2031 | E7: 86.93 | F7: 86.93 | G7: 86.93 | H7: =_xlfn.XLOOKUP(B7,'28'!$A:$A,'28'!$G:$G,"pipino il breve") -> 86.88 | I7: =_xlfn.XLOOKUP(B7,'29'!$A:$A,'29'!$G:$G,"pipino il breve") -> 86.91 | J7: =_xlfn.XLOOKUP(B7,'30'!$A:$A,'30'!$G:$G,"pipino il breve") -> 87.13 | K7: =_xlfn.XLOOKUP(B7,'30'!$A:$A,'30'!$G:$G,"pipino il breve") -> 87.13 | L7: =_xlfn.XLOOKUP(B7,'2'!$A:$A,'2'!$G:$G,"pipino il breve") -> 86.86 | M7: =_xlfn.XLOOKUP(B7,'2'!$A:$A,'2'!$G:$G,"pipino il breve") -> 86.86 | N7: =_xlfn.XLOOKUP(B7,'2'!$A:$A,'2'!$G:$G,"pipino il breve") -> 86.86 | O7: =_xlfn.XLOOKUP(B7,'5'!$A:$A,'5'!$G:$G,"pipino il breve") -> 86.92 | P7: =_xlfn.XLOOKUP(B7,'6'!$A:$A,'6'!$G:$G,"pipino il breve") -> 86.92 | Q7: =_xlfn.XLOOKUP(B7,'7'!$A:$A,'7'!$G:$G,"pipino il breve") -> 87.2 | R7: =_xlfn.XLOOKUP(B7,'8'!$A:$A,'8'!$G:$G,"pipino il breve") -> 87.1 | S7: =_xlfn.XLOOKUP(B7,'9'!$A:$A,'9'!$G:$G,"pipino il breve") -> 86.94 | T7: =_xlfn.XLOOKUP(B7,'9'!$A:$A,'9'!$G:$G,"pipino il breve") -> 86.94 | U7: =_xlfn.XLOOKUP(B7,'9'!$A:$A,'9'!$G:$G,"pipino il breve") -> 86.94 | V7: =_xlfn.XLOOKUP(B7,'12'!$A:$A,'12'!$G:$G,"pipino il breve") -> 86.51 | W7: =_xlfn.XLOOKUP(B7,'13'!$A:$A,'13'!$G:$G,"pipino il breve") -> 86.4 | X7: =_xlfn.XLOOKUP(B7,'14'!$A:$A,'14'!$G:$G,"pipino il breve") -> 86.36 | Y7: =_xlfn.XLOOKUP(B7,'15'!$A:$A,'15'!$G:$G,"pipino il breve") -> 86.7 | Z7: =_xlfn.XLOOKUP(B7,'16'!$A:$A,'16'!$G:$G,"pipino il breve") -> 86.91 | AA7: =_xlfn.XLOOKUP(B7,'16'!$A:$A,'16'!$G:$G,"pipino il breve") -> 86.91 | AB7: =_xlfn.XLOOKUP(B7,'16'!$A:$A,'16'!$G:$G,"pipino il breve") -> 86.91 | AC7: =_xlfn.XLOOKUP(B7,'19'!$A:$A,'19'!$G:$G,"pipino il breve") -> 86.98 | AD7: =_xlfn.XLOOKUP(B7,'20'!$A:$A,'20'!$G:$G,"pipino il breve") -> 86.97 | AE7: =_xlfn.XLOOKUP(B7,'21'!$A:$A,'21'!$G:$G,"pipino il breve") -> 86.83 | AF7: =_xlfn.XLOOKUP(B7,'22'!$A:$A,'22'!$G:$G,"pipino il breve") -> 86.79 | AG7: =_xlfn.XLOOKUP(B7,'23'!$A:$A,'23'!$G:$G,"pipino il breve") -> 87.07 | AH7: =_xlfn.XLOOKUP(B7,'23'!$A:$A,'23'!$G:$G,"pipino il breve") -> 87.07 | AI7: =_xlfn.XLOOKUP(B7,'23'!$A:$A,'23'!$G:$G,"pipino il breve") -> 87.07 | AJ7: =_xlfn.XLOOKUP(B7,'26'!$A:$A,'26'!$G:$G,"pipino il breve") -> 87.21 | AK7: =_xlfn.XLOOKUP(B7,'27'!$A:$A,'27'!$G:$G,"pipino il breve") -> 87.28
A8: 7 | B8: IT0004923998 | C8: 2.375 | D8: 01/09/2044 | E8: 108.74 | F8: 108.74 | G8: 108.74 | H8: =_xlfn.XLOOKUP(B8,'28'!$A:$A,'28'!$G:$G,"pipino il breve") -> 108.57 | I8: =_xlfn.XLOOKUP(B8,'29'!$A:$A,'29'!$G:$G,"pipino il breve") -> 108.41 | J8: =_xlfn.XLOOKUP(B8,'30'!$A:$A,'30'!$G:$G,"pipino il breve") -> 108.82 | K8: =_xlfn.XLOOKUP(B8,'30'!$A:$A,'30'!$G:$G,"pipino il breve") -> 108.82 | L8: =_xlfn.XLOOKUP(B8,'2'!$A:$A,'2'!$G:$G,"pipino il breve") -> 108.14 | M8: =_xlfn.XLOOKUP(B8,'2'!$A:$A,'2'!$G:$G,"pipino il breve") -> 108.14 | N8: =_xlfn.XLOOKUP(B8,'2'!$A:$A,'2'!$G:$G,"pipino il breve") -> 108.14 | O8: =_xlfn.XLOOKUP(B8,'5'!$A:$A,'5'!$G:$G,"pipino il breve") -> 108.34 | P8: =_xlfn.XLOOKUP(B8,'6'!$A:$A,'6'!$G:$G,"pipino il breve") -> 108.05 | Q8: =_xlfn.XLOOKUP(B8,'7'!$A:$A,'7'!$G:$G,"pipino il breve") -> 108.96 | R8: =_xlfn.XLOOKUP(B8,'8'!$A:$A,'8'!$G:$G,"pipino il breve") -> 108.58 | S8: =_xlfn.XLOOKUP(B8,'9'!$A:$A,'9'!$G:$G,"pipino il breve") -> 108.15 | T8: =_xlfn.XLOOKUP(B8,'9'!$A:$A,'9'!$G:$G,"pipino il breve") -> 108.15 | U8: =_xlfn.XLOOKUP(B8,'9'!$A:$A,'9'!$G:$G,"pipino il breve") -> 108.15 | V8: =_xlfn.XLOOKUP(B8,'12'!$A:$A,'12'!$G:$G,"pipino il breve") -> 107.6 | W8: =_xlfn.XLOOKUP(B8,'13'!$A:$A,'13'!$G:$G,"pipino il breve") -> 107.16 | X8: =_xlfn.XLOOKUP(B8,'14'!$A:$A,'14'!$G:$G,"pipino il breve") -> 107.17 | Y8: =_xlfn.XLOOKUP(B8,'15'!$A:$A,'15'!$G:$G,"pipino il breve") -> 108.08 | Z8: =_xlfn.XLOOKUP(B8,'16'!$A:$A,'16'!$G:$G,"pipino il breve") -> 108.6 | AA8: =_xlfn.XLOOKUP(B8,'16'!$A:$A,'16'!$G:$G,"pipino il breve") -> 108.6 | AB8: =_xlfn.XLOOKUP(B8,'16'!$A:$A,'16'!$G:$G,"pipino il breve") -> 108.6 | AC8: =_xlfn.XLOOKUP(B8,'19'!$A:$A,'19'!$G:$G,"pipino il breve") -> 108.6 | AD8: =_xlfn.XLOOKUP(B8,'20'!$A:$A,'20'!$G:$G,"pipino il breve") -> 108.17 | AE8: =_xlfn.XLOOKUP(B8,'21'!$A:$A,'21'!$G:$G,"pipino il breve") -> 107.78 | AF8: =_xlfn.XLOOKUP(B8,'22'!$A:$A,'22'!$G:$G,"pipino il breve") -> 107.3 | AG8: =_xlfn.XLOOKUP(B8,'23'!$A:$A,'23'!$G:$G,"pipino il breve") -> 107.98 | AH8: =_xlfn.XLOOKUP(B8,'23'!$A:$A,'23'!$G:$G,"pipino il breve") -> 107.98 | AI8: =_xlfn.XLOOKUP(B8,'23'!$A:$A,'23'!$G:$G,"pipino il breve") -> 107.98 | AJ8: =_xlfn.XLOOKUP(B8,'26'!$A:$A,'26'!$G:$G,"pipino il breve") -> 108.56 | AK8: =_xlfn.XLOOKUP(B8,'27'!$A:$A,'27'!$G:$G,"pipino il breve") -> 109.24
